Workbook

Sheet Ingresos
B2: PANEL DE INGRESOS
D5: =#REF! & " " & TEXT(SUM(tbl_ingresos[Ingreso Total]),"#,##0.00") -> #REF! | F5: =#REF! & " " & TEXT(SUM(tbl_ingresos[Valor Impuesto]),"#,##0.00") -> #REF! | H5: =#REF! & " " & TEXT(SUM(tbl_ingresos[Total Neto]),"#,##0.00") -> #REF!
D6: Ingresos Brutos | F6: Monto de Impuestos | H6: Ingresos Netos
B8: ID | C8: Fecha | D8: Categoría | E8: Descripción | F8: Mét. De Pago | G8: Ingreso Total | H8: Impuesto | I8: Valor Impuesto | J8: Total Neto | K8: Notas | L8: M | M8: Y | N8: D
B9: 301 | C9: 46105 | D9: 301 Ventas factura/Clientes | E9: Fac 621 | F9: Transferencias | G9: 1288412 | H9: 0.19 | I9: =G9 - (G9 / (1 + H9)) -> 205712.84 | J9: =G9 / (1 + H9) -> 1082699.2 | K9: I. Municipalidad de Temuco. | L9: =IF(C9="","",MONTH(C9)) -> 3 | M9: =IF(C9="","",YEAR(C9)) -> 2026 | N9: =IF(C9="","",DAY(C9)) -> 24
C10: 46084 | D10: 302 Fingo/ Flujo | E10: F.616 | F10: TRANSFERENCIA FINGO | G10: 874949 | K10: MONTO FACTURA 969.882 COMISION DE 94.933 | L10: 94933
C11: 46084 | D11: 302 Fingo/ Flujo | E11: F618 | F11: TRANSFERENCIA FINGO | G11: 518767 | H11: 0.19 | I11: =G11 - (G11 / (1 + H11)) -> 82828.345 | J11: =G11 / (1 + H11) -> 435938.66 | K11: MONTO FACTURA 545.273 COMISION 26.506 | L11: =IF(C11="","",MONTH(C11)) -> 3 | M11: =IF(C11="","",YEAR(C11)) -> 2026 | N11: =IF(C11="","",DAY(C11)) -> 3
C12: 46090 | D12: 302 Fingo/ Flujo | E12: 617 Y 622 | F12: TRANSFERENCIA FINGO | G12: 1349393 | H12: 0.19 | I12: =G12 - (G12 / (1 + H12)) -> 215449.3 | J12: =G12 / (1 + H12) -> 1133943.7 | K12: MONTO FACATURAS 2.103.773 SE PAGO FACTURA TALCA POR 594.952 | L12: =IF(C12="","",MONTH(C12)) -> 3 | M12: =IF(C12="","",YEAR(C12)) -> 2026 | N12: =IF(C12="","",DAY(C12)) -> 9
C13: 46091 | D13: 302 Fingo/ Flujo | E13: F | F13: TRANSFERENCIA FINGO | G13: 1005305 | H13: 0.19 | I13: =G13 - (G13 / (1 + H13)) -> 160510.88 | J13: =G13 / (1 + H13) -> 844794.12 | K13: MONTO FACTURA 1.105.009 COMISION 99.704 | L13: =IF(C13="","",MONTH(C13)) -> 3 | M13: =IF(C13="","",YEAR(C13)) -> 2026 | N13: =IF(C13="","",DAY(C13)) -> 10
C14: 46097 | D14: 302 Fingo/ Flujo | E14: F 631 | F14: TRANSFERENCIA FINGO | G14: 852599 | H14: 0.19 | I14: =G14 - (G14 / (1 + H14)) -> 136129.25 | J14: =G14 / (1 + H14) -> 716469.75 | K14: MONTO FACTURA 949.506 COMISION 96.907 | L14: =IF(C14="","",MONTH(C14)) -> 3 | M14: =IF(C14="","",YEAR(C14)) -> 2026 | N14: =IF(C14="","",DAY(C14)) -> 16
C15: 46100 | D15: 302 Fingo/ Flujo | E15: F.632 | F15: TRANSFERENCIA FINGO | G15: 269948 | H15: 0.19 | I15: =G15 - (G15 / (1 + H15)) -> 43100.941 | J15: =G15 / (1 + H15) -> 226847.06 | K15: MONTO FACTURA 326.404 COMISION 56.456 | L15: =IF(C15="","",MONTH(C15)) -> 3 | M15: =IF(C15="","",YEAR(C15)) -> 2026 | N15: =IF(C15="","",DAY(C15)) -> 19
C16: 46104 | D16: 302 Fingo/ Flujo | E16: F.635 | F16: TRANSFERENCIA FINGO | G16: 397891 | H16: 0.19 | I16: =G16 - (G16 / (1 + H16)) -> 63528.815 | J16: =G16 / (1 + H16) -> 334362.18 | K16: MONTO FACTURA 615.140 PAGO FACTURA RETIRO POR 238.964 | L16: =IF(C16="","",MONTH(C16)) -> 3 | M16: =IF(C16="","",YEAR(C16)) -> 2026 | N16: =IF(C16="","",DAY(C16)) -> 23
C17: 46104 | D17: 302 Fingo/ Flujo | E17: EXCEDENTES | F17: TRANSFERENCIA FINGO | G17: 277250 | H17: 0.19 | I17: =G17 - (G17 / (1 + H17)) -> 44266.807 | J17: =G17 / (1 + H17) -> 232983.19 | K17: EXCEDENTES | L17: =IF(C17="","",MONTH(C17)) -> 3 | M17: =IF(C17="","",YEAR(C17)) -> 2026 | N17: =IF(C17="","",DAY(C17)) -> 23
C18: 46087 | D18: 301 Ventas factura/Clientes | E18: F 604 | F18: TRANSFERENCIA CLIENTES | G18: 128225 | H18: 0.19 | I18: =G18 - (G18 / (1 + H18)) -> 20472.899 | J18: =G18 / (1 + H18) -> 107752.1 | K18: TESORERIA PROVINCIAL DE MALLECO ANGOL | L18: =IF(C18="","",MONTH(C18)) -> 3 | M18: =IF(C18="","",YEAR(C18)) -> 2026 | N18: =IF(C18="","",DAY(C18)) -> 6
C19: 46090 | D19: 301 Ventas factura/Clientes | E19: F 589 | F19: TRANSFERENCIA CLIENTES | G19: 371542 | H19: 0.19 | I19: =G19 - (G19 / (1 + H19)) -> 59321.832 | J19: =G19 / (1 + H19) -> 312220.17 | K19: MODULOS WEWFE LIMITADA | L19: =IF(C19="","",MONTH(C19)) -> 3 | M19: =IF(C19="","",YEAR(C19)) -> 2026 | N19: =IF(C19="","",DAY(C19)) -> 9
C20: 46092 | D20: 301 Ventas factura/Clientes | E20: 598 | F20: TRANSFERENCIA CLIENTES | G20: 128484 | H20: 0.19 | I20: =G20 - (G20 / (1 + H20)) -> 20514.252 | J20: =G20 / (1 + H20) -> 107969.75 | K20: ILUSTRE MUNICIPALIDAD DE NINHUE DEPARTAMENTO DE SALUD | L20: =IF(C20="","",MONTH(C20)) -> 3 | M20: =IF(C20="","",YEAR(C20)) -> 2026 | N20: =IF(C20="","",DAY(C20)) -> 11
C21: 46094 | D21: 301 Ventas factura/Clientes | F21: TRANSFERENCIA CLIENTES | G21: 96271 | H21: 0.19 | I21: =G21 - (G21 / (1 + H21)) -> 15371 | J21: =G21 / (1 + H21) -> 80900 | K21: PAGO CLIENTES | L21: =IF(C21="","",MONTH(C21)) -> 3 | M21: =IF(C21="","",YEAR(C21)) -> 2026 | N21: =IF(C21="","",DAY(C21)) -> 13
C22: 46100 | D22: 301 Ventas factura/Clientes | F22: TRANSFERENCIA CLIENTES | G22: 333855 | H22: 0.19 | I22: =G22 - (G22 / (1 + H22)) -> 53304.58 | J22: =G22 / (1 + H22) -> 280550.42 | K22: PAGO CLIENTES | L22: =IF(C22="","",MONTH(C22)) -> 3 | M22: =IF(C22="","",YEAR(C22)) -> 2026 | N22: =IF(C22="","",DAY(C22)) -> 19
C23: 46101 | D23: 301 Ventas factura/Clientes | E23: 626 | F23: TRANSFERENCIA CLIENTES | G23: 22872 | H23: 0.19 | I23: =G23 - (G23 / (1 + H23)) -> 3651.8319 | J23: =G23 / (1 + H23) -> 19220.168 | K23: MUNICIPLAIDAD LAGO RANCO | L23: =IF(C23="","",MONTH(C23)) -> 3 | M23: =IF(C23="","",YEAR(C23)) -> 2026 | N23: =IF(C23="","",DAY(C23)) -> 20
C24: 46101 | D24: 301 Ventas factura/Clientes | E24: 625 | F24: TRANSFERENCIA CLIENTES | G24: 20635 | H24: 0.19 | I24: =G24 - (G24 / (1 + H24)) -> 3294.6639 | J24: =G24 / (1 + H24) -> 17340.336 | K24: MUNICIPLAIDAD LAGO RANCO | L24: =IF(C24="","",MONTH(C24)) -> 3 | M24: =IF(C24="","",YEAR(C24)) -> 2026 | N24: =IF(C24="","",DAY(C24)) -> 20
C25: 46101 | D25: 301 Ventas factura/Clientes | E25: 624 | F25: TRANSFERENCIA CLIENTES | G25: 88607 | H25: 0.19 | I25: =G25 - (G25 / (1 + H25)) -> 14147.336 | J25: =G25 / (1 + H25) -> 74459.664 | K25: MUNICIPLAIDAD LAGO RANCO | L25: =IF(C25="","",MONTH(C25)) -> 3 | M25: =IF(C25="","",YEAR(C25)) -> 2026 | N25: =IF(C25="","",DAY(C25)) -> 20
C26: 24-3-206 | D26: 301 Ventas factura/Clientes | E26: 621 | F26: TRANSFERENCIA CLIENTES | G26: 1288412 | H26: 0.19 | I26: =G26 - (G26 / (1 + H26)) -> 205712.84 | J26: =G26 / (1 + H26) -> 1082699.2 | K26: MUNICIPALIDAD DE TEMUCO | L26: =IF(C26="","",MONTH(C26)) -> #VALUE! | M26: =IF(C26="","",YEAR(C26)) -> #VALUE! | N26: =IF(C26="","",DAY(C26)) -> #VALUE!
H27: 0.19 | I27: =G27 - (G27 / (1 + H27)) -> 0 | J27: =G27 / (1 + H27) -> 0 | L27: =IF(C27="","",MONTH(C27)) | M27: =IF(C27="","",YEAR(C27)) | N27: =IF(C27="","",DAY(C27))
H28: 0.19 | I28: =G28 - (G28 / (1 + H28)) -> 0 | J28: =G28 / (1 + H28) -> 0 | L28: =IF(C28="","",MONTH(C28)) | M28: =IF(C28="","",YEAR(C28)) | N28: =IF(C28="","",DAY(C28))
H29: 0.19 | I29: =G29 - (G29 / (1 + H29)) -> 0 | J29: =G29 / (1 + H29) -> 0 | L29: =IF(C29="","",MONTH(C29)) | M29: =IF(C29="","",YEAR(C29)) | N29: =IF(C29="","",DAY(C29))
H30: 0.19 | I30: =G30 - (G30 / (1 + H30)) -> 0 | J30: =G30 / (1 + H30) -> 0 | L30: =IF(C30="","",MONTH(C30)) | M30: =IF(C30="","",YEAR(C30)) | N30: =IF(C30="","",DAY(C30))
H31: 0.19 | I31: =G31 - (G31 / (1 + H31)) -> 0 | J31: =G31 / (1 + H31) -> 0 | L31: =IF(C31="","",MONTH(C31)) | M31: =IF(C31="","",YEAR(C31)) | N31: =IF(C31="","",DAY(C31))
H32: 0.19 | I32: =G32 - (G32 / (1 + H32)) -> 0 | J32: =G32 / (1 + H32) -> 0 | L32: =IF(C32="","",MONTH(C32)) | M32: =IF(C32="","",YEAR(C32)) | N32: =IF(C32="","",DAY(C32))
H33: 0.19 | I33: =G33 - (G33 / (1 + H33)) -> 0 | J33: =G33 / (1 + H33) -> 0 | L33: =IF(C33="","",MONTH(C33)) | M33: =IF(C33="","",YEAR(C33)) | N33: =IF(C33="","",DAY(C33))
H34: 0.19 | I34: =G34 - (G34 / (1 + H34)) -> 0 | J34: =G34 / (1 + H34) -> 0 | L34: =IF(C34="","",MONTH(C34)) | M34: =IF(C34="","",YEAR(C34)) | N34: =IF(C34="","",DAY(C34))
H35: 0.19 | I35: =G35 - (G35 / (1 + H35)) -> 0 | J35: =G35 / (1 + H35) -> 0 | L35: =IF(C35="","",MONTH(C35)) | M35: =IF(C35="","",YEAR(C35)) | N35: =IF(C35="","",DAY(C35))
H36: 0.19 | I36: =G36 - (G36 / (1 + H36)) -> 0 | J36: =G36 / (1 + H36) -> 0 | L36: =IF(C36="","",MONTH(C36)) | M36: =IF(C36="","",YEAR(C36)) | N36: =IF(C36="","",DAY(C36))
H37: 0.19 | I37: =G37 - (G37 / (1 + H37)) -> 0 | J37: =G37 / (1 + H37) -> 0 | L37: =IF(C37="","",MONTH(C37)) | M37: =IF(C37="","",YEAR(C37)) | N37: =IF(C37="","",DAY(C37))
H38: 0.19 | I38: =G38 - (G38 / (1 + H38)) -> 0 | J38: =G38 / (1 + H38) -> 0 | L38: =IF(C38="","",MONTH(C38)) | M38: =IF(C38="","",YEAR(C38)) | N38: =IF(C38="","",DAY(C38))
... H97: 0.19 | I97: =G97 - (G97 / (1 + H97)) -> 0 | J97: =G97 / (1 + H97) -> 0 | L97: =IF(C97="","",MONTH(C97)) | M97: =IF(C97="","",YEAR(C97)) | N97: =IF(C97="","",DAY(C97))
I98: =G98 - (G98 / (1 + H98)) -> 0 | J98: =G98 / (1 + H98) -> 0 | L98: =IF(C98="","",MONTH(C98)) | M98: =IF(C98="","",YEAR(C98)) | N98: =IF(C98="","",DAY(C98))
I99: =G99 - (G99 / (1 + H99)) -> 0 | J99: =G99 / (1 + H99) -> 0 | L99: =IF(C99="","",MONTH(C99)) | M99: =IF(C99="","",YEAR(C99)) | N99: =IF(C99="","",DAY(C99))

Sheet Gastos
B2: PANEL DE GASTOS
D5: =#REF! & " " & TEXT(SUM(tbl_ingresos3[Gasto Total]),"#,##0.00") -> #REF! | F5: =#REF! & " " & TEXT(SUM(tbl_ingresos3[Valor Impuesto]),"#,##0.00") -> #REF! | H5: =#REF! & " " & TEXT(SUM(tbl_ingresos3[Total Neto]),"#,##0.00") -> #REF!
D6: Gastos Brutos | F6: Monto de Impuestos | H6: Gastos Netos
B8: ID | C8: Fecha | D8: Categoría | E8: Descripción | F8: Mét. De Pago | G8: Gasto Total | H8: Impuesto | I8: Valor Impuesto | J8: Total Neto | K8: Notas | L8: M | M8: Y | N8: D
B9: 415 | C9: 45740 | D9: 415 Devolucion Capital | E9: Ingreso del 6-08-25 | F9: Transferencias | G9: 1200000 | H9: 0 | I9: =G9 - (G9 / (1 + H9)) -> 0 | J9: =G9 / (1 + H9) -> 1200000 | K9: Prestamo de V. R a EXT.Real | L9: =IF(C9="","",MONTH(C9)) -> 3 | M9: =IF(C9="","",YEAR(C9)) -> 2025 | N9: =IF(C9="","",DAY(C9)) -> 24
B10: 408 | C10: 46112 | D10: 408 Sueldo administrativos/oficina | E10: pendiente 406.309 | F10: Transferencias B. Santader | G10: 594952 | H10: 0 | I10: =G10 - (G10 / (1 + H10)) -> 0 | J10: =G10 / (1 + H10) -> 594952 | K10: pendiente 406.309 | L10: =IF(C10="","",MONTH(C10)) -> 3 | M10: =IF(C10="","",YEAR(C10)) -> 2026 | N10: =IF(C10="","",DAY(C10)) -> 31
B11: 404 | C11: 46097 | D11: 404 Arriendo | E11: Oficina | F11: Transferencias B. Santader | G11: 673240 | H11: 0 | I11: =G11 - (G11 / (1 + H11)) -> 0 | J11: =G11 / (1 + H11) -> 673240 | K11: pago a Gabriel Lopez | L11: =IF(C11="","",MONTH(C11)) -> 3 | M11: =IF(C11="","",YEAR(C11)) -> 2026 | N11: =IF(C11="","",DAY(C11)) -> 16
C12: 46086 | D12: 416 Oficina | E12: Alimento | F12: Debito B. Santander 2405 | G12: 8800 | H12: 0 | I12: =G12 - (G12 / (1 + H12)) -> 0 | J12: =G12 / (1 + H12) -> 8800 | L12: =IF(C12="","",MONTH(C12)) -> 3 | M12: =IF(C12="","",YEAR(C12)) -> 2026 | N12: =IF(C12="","",DAY(C12)) -> 5
C13: 46100 | D13: 416 Oficina | E13: Gastos oficina varios | F13: Transferencias B. Santader | G13: 100000 | H13: 0 | I13: =G13 - (G13 / (1 + H13)) -> 0 | J13: =G13 / (1 + H13) -> 100000 | K13: varios oficina | L13: =IF(C13="","",MONTH(C13)) -> 3 | M13: =IF(C13="","",YEAR(C13)) -> 2026 | N13: =IF(C13="","",DAY(C13)) -> 19
C14: 46104 | D14: 407 Reunión clientes-personal | E14: personal | F14: Transferencias B. Santader | G14: 20000 | H14: 0 | I14: =G14 - (G14 / (1 + H14)) -> 0 | J14: =G14 / (1 + H14) -> 20000 | K14: reunion personal | L14: =IF(C14="","",MONTH(C14)) -> 3 | M14: =IF(C14="","",YEAR(C14)) -> 2026 | N14: =IF(C14="","",DAY(C14)) -> 23
C15: 46085 | D15: 407 Reunión clientes-personal | E15: CLIENTE | F15: Debito B. Santander 2405 | G15: 9800 | H15: 0 | I15: =G15 - (G15 / (1 + H15)) -> 0 | J15: =G15 / (1 + H15) -> 9800 | K15: REUNION CLIENTE | L15: =IF(C15="","",MONTH(C15)) -> 3 | M15: =IF(C15="","",YEAR(C15)) -> 2026 | N15: =IF(C15="","",DAY(C15)) -> 4
C16: 46084 | D16: 407 Reunión clientes-personal | E16: personal | F16: Debito B. Santander 2405 | G16: 8140 | H16: 0 | I16: =G16 - (G16 / (1 + H16)) -> 0 | J16: =G16 / (1 + H16) -> 8140 | K16: reunion personal | L16: =IF(C16="","",MONTH(C16)) -> 3 | M16: =IF(C16="","",YEAR(C16)) -> 2026 | N16: =IF(C16="","",DAY(C16)) -> 3
C17: 46126 | D17: 410 Telefonía | E17: CLARO | F17: Debito B. Santander 2405 | G17: 8125 | H17: 0.19 | I17: =G17 - (G17 / (1 + H17)) -> 1297.2689 | J17: =G17 / (1 + H17) -> 6827.7311 | L17: =IF(C17="","",MONTH(C17)) -> 4 | M17: =IF(C17="","",YEAR(C17)) -> 2026 | N17: =IF(C17="","",DAY(C17)) -> 14
C18: 46126 | D18: 410 Telefonía | E18: ENTEL EMPRESA | F18: Debito B. Santander 2405 | G18: 43228 | H18: 0.19 | I18: =G18 - (G18 / (1 + H18)) -> 6901.9496 | J18: =G18 / (1 + H18) -> 36326.05 | L18: =IF(C18="","",MONTH(C18)) -> 4 | M18: =IF(C18="","",YEAR(C18)) -> 2026 | N18: =IF(C18="","",DAY(C18)) -> 14
C19: 46126 | D19: 408 Sueldo administrativos/oficina | E19: DIFERENCIA SUELDO MARZO | F19: Debito B. Santander 2405 | G19: 470000 | H19: 0.19 | I19: =G19 - (G19 / (1 + H19)) -> 75042.017 | J19: =G19 / (1 + H19) -> 394957.98 | K19: 63691 DIFERENCIA A FAVOR DE V.R | L19: =IF(C19="","",MONTH(C19)) -> 4 | M19: =IF(C19="","",YEAR(C19)) -> 2026 | N19: =IF(C19="","",DAY(C19)) -> 14
C20: 46126 | D20: 404 Arriendo | E20: ARRIENDO OFICINA | F20: Debito B. Santander 2405 | G20: 673240 | H20: 0.19 | I20: =G20 - (G20 / (1 + H20)) -> 107492.1 | J20: =G20 / (1 + H20) -> 565747.9 | K20: GABRIEL LOPEZ | L20: =IF(C20="","",MONTH(C20)) -> 4 | M20: =IF(C20="","",YEAR(C20)) -> 2026 | N20: =IF(C20="","",DAY(C20)) -> 14
C21: 46127 | D21: 409 Imposiciones administrativo | E21: OCTUBRE-NOVIEMBRE SALDO A CONTADOR | F21: Transferencias B. Santader | G21: 737351 | H21: 0.19 | I21: =G21 - (G21 / (1 + H21)) -> 117728.31 | J21: =G21 / (1 + H21) -> 619622.69 | K21: PREVIRED PEDIR REMMBOLSO AFP CAPITAL | L21: =IF(C21="","",MONTH(C21)) -> 4 | M21: =IF(C21="","",YEAR(C21)) -> 2026 | N21: =IF(C21="","",DAY(C21)) -> 15
C22: 46127 | D22: 409 Imposiciones administrativo | E22: AFC OCTUBRE | F22: Transferencias B. Santader | G22: 156027 | H22: 0.19 | I22: =G22 - (G22 / (1 + H22)) -> 24911.874 | J22: =G22 / (1 + H22) -> 131115.13 | K22: MARICEL | L22: =IF(C22="","",MONTH(C22)) -> 4 | M22: =IF(C22="","",YEAR(C22)) -> 2026 | N22: =IF(C22="","",DAY(C22)) -> 15
C23: 46126 | H23: 0.19 | I23: =G23 - (G23 / (1 + H23)) -> 0 | J23: =G23 / (1 + H23) -> 0 | L23: =IF(C23="","",MONTH(C23)) -> 4 | M23: =IF(C23="","",YEAR(C23)) -> 2026 | N23: =IF(C23="","",DAY(C23)) -> 14
H24: 0.19 | I24: =G24 - (G24 / (1 + H24)) -> 0 | J24: =G24 / (1 + H24) -> 0 | L24: =IF(C24="","",MONTH(C24)) | M24: =IF(C24="","",YEAR(C24)) | N24: =IF(C24="","",DAY(C24))
C25: 3 MARZO 2026 | H25: 0.19 | I25: =G25 - (G25 / (1 + H25)) -> 0 | J25: =G25 / (1 + H25) -> 0 | L25: =IF(C25="","",MONTH(C25)) -> 3 | M25: =IF(C25="","",YEAR(C25)) -> 2026 | N25: =IF(C25="","",DAY(C25)) -> 3
H26: 0.19 | I26: =G26 - (G26 / (1 + H26)) -> 0 | J26: =G26 / (1 + H26) -> 0 | L26: =IF(C26="","",MONTH(C26)) | M26: =IF(C26="","",YEAR(C26)) | N26: =IF(C26="","",DAY(C26))
H27: 0.19 | I27: =G27 - (G27 / (1 + H27)) -> 0 | J27: =G27 / (1 + H27) -> 0 | L27: =IF(C27="","",MONTH(C27)) | M27: =IF(C27="","",YEAR(C27)) | N27: =IF(C27="","",DAY(C27))
H28: 0.19 | I28: =G28 - (G28 / (1 + H28)) -> 0 | J28: =G28 / (1 + H28) -> 0 | L28: =IF(C28="","",MONTH(C28)) | M28: =IF(C28="","",YEAR(C28)) | N28: =IF(C28="","",DAY(C28))
H29: 0.19 | I29: =G29 - (G29 / (1 + H29)) -> 0 | J29: =G29 / (1 + H29) -> 0 | L29: =IF(C29="","",MONTH(C29)) | M29: =IF(C29="","",YEAR(C29)) | N29: =IF(C29="","",DAY(C29))
H30: 0.19 | I30: =G30 - (G30 / (1 + H30)) -> 0 | J30: =G30 / (1 + H30) -> 0 | L30: =IF(C30="","",MONTH(C30)) | M30: =IF(C30="","",YEAR(C30)) | N30: =IF(C30="","",DAY(C30))
H31: 0.19 | I31: =G31 - (G31 / (1 + H31)) -> 0 | J31: =G31 / (1 + H31) -> 0 | L31: =IF(C31="","",MONTH(C31)) | M31: =IF(C31="","",YEAR(C31)) | N31: =IF(C31="","",DAY(C31))
H32: 0.19 | I32: =G32 - (G32 / (1 + H32)) -> 0 | J32: =G32 / (1 + H32) -> 0 | L32: =IF(C32="","",MONTH(C32)) | M32: =IF(C32="","",YEAR(C32)) | N32: =IF(C32="","",DAY(C32))
H33: 0.19 | I33: =G33 - (G33 / (1 + H33)) -> 0 | J33: =G33 / (1 + H33) -> 0 | L33: =IF(C33="","",MONTH(C33)) | M33: =IF(C33="","",YEAR(C33)) | N33: =IF(C33="","",DAY(C33))
H34: 0.19 | I34: =G34 - (G34 / (1 + H34)) -> 0 | J34: =G34 / (1 + H34) -> 0 | L34: =IF(C34="","",MONTH(C34)) | M34: =IF(C34="","",YEAR(C34)) | N34: =IF(C34="","",DAY(C34))
H35: 0.19 | I35: =G35 - (G35 / (1 + H35)) -> 0 | J35: =G35 / (1 + H35) -> 0 | L35: =IF(C35="","",MONTH(C35)) | M35: =IF(C35="","",YEAR(C35)) | N35: =IF(C35="","",DAY(C35))
H36: 0.19 | I36: =G36 - (G36 / (1 + H36)) -> 0 | J36: =G36 / (1 + H36) -> 0 | L36: =IF(C36="","",MONTH(C36)) | M36: =IF(C36="","",YEAR(C36)) | N36: =IF(C36="","",DAY(C36))
H37: 0.19 | I37: =G37 - (G37 / (1 + H37)) -> 0 | J37: =G37 / (1 + H37) -> 0 | L37: =IF(C37="","",MONTH(C37)) | M37: =IF(C37="","",YEAR(C37)) | N37: =IF(C37="","",DAY(C37))
... H133: 0.19 | I133: =G133 - (G133 / (1 + H133)) -> 0 | J133: =G133 / (1 + H133) -> 0 | L133: =IF(C133="","",MONTH(C133)) | M133: =IF(C133="","",YEAR(C133)) | N133: =IF(C133="","",DAY(C133))

Sheet Costos
B2: PANEL DE COSTOS
D5: =#REF! & " " & TEXT(SUM(tbl_ingresos314[Costo Total]),"#,##0.00") -> #REF! | F5: =#REF! & " " & TEXT(SUM(tbl_ingresos314[Valor Impuesto]),"#,##0.00") -> #REF! | H5: =#REF! & " " & TEXT(SUM(tbl_ingresos314[Total Neto]),"#,##0.00") -> #REF!
D6: Costos Brutos | F6: Monto de Impuestos | H6: Costos Netos
B8: ID | C8: Fecha | D8: Categoría | E8: Descripción | F8: Mét. De Pago | G8: Costo Total | H8: Impuesto | I8: Valor Impuesto | J8: Total Neto | K8: Notas | L8: M | M8: Y | N8: D
C9: MARZO 2026 | I9: =G9 - (G9 / (1 + H9)) -> 0 | J9: =G9 / (1 + H9) -> 0 | L9: =IF(C9="","",MONTH(C9)) -> #VALUE! | M9: =IF(C9="","",YEAR(C9)) -> #VALUE! | N9: =IF(C9="","",DAY(C9)) -> #VALUE!
B10: 514 | C10: 46105 | D10: 514materiales/varios | E10: Motobomba | F10: Debito | G10: 242240 | H10: 0.19 | I10: =G10 - (G10 / (1 + H10)) -> 38676.975 | J10: =G10 / (1 + H10) -> 203563.03 | K10: mantención Red Seca | L10: =IF(C10="","",MONTH(C10)) -> 3 | M10: =IF(C10="","",YEAR(C10)) -> 2026 | N10: =IF(C10="","",DAY(C10)) -> 24
B11: 502 | C11: 46106 | D11: 502 Fire Master-Ossa-Startfire | E11: Ext. Soporte, Piton | F11: Debito | G11: 157865 | H11: 0.19 | I11: =G11 - (G11 / (1 + H11)) -> 25205.336 | J11: =G11 / (1 + H11) -> 132659.66 | K11: Fac 33276/FireMaster | L11: =IF(C11="","",MONTH(C11)) -> 3 | M11: =IF(C11="","",YEAR(C11)) -> 2026 | N11: =IF(C11="","",DAY(C11)) -> 25
B12: 505 | C12: 46106 | D12: 505 Ecoex / Transporte insumo | E12: O.T 010-23-379753 | F12: Efectivo | G12: 17000 | H12: 0.19 | I12: =G12 - (G12 / (1 + H12)) -> 2714.2857 | J12: =G12 / (1 + H12) -> 14285.714 | K12: Retiro pedido fireMaster-Fac 33276 | L12: =IF(C12="","",MONTH(C12)) -> 3 | M12: =IF(C12="","",YEAR(C12)) -> 2026 | N12: =IF(C12="","",DAY(C12)) -> 25
B13: 515 | C13: 46106 | D13: 515 Transporte/Combustible | E13: DYFX20 | F13: Debito | G13: 20000 | H13: 0.19 | I13: =G13 - (G13 / (1 + H13)) -> 3193.2773 | J13: =G13 / (1 + H13) -> 16806.723 | K13: camioneta transporte de herramientas | L13: =IF(C13="","",MONTH(C13)) -> 3 | M13: =IF(C13="","",YEAR(C13)) -> 2026 | N13: =IF(C13="","",DAY(C13)) -> 25
L14: =IF(C14="","",MONTH(C14)) | M14: =IF(C14="","",YEAR(C14)) | N14: =IF(C14="","",DAY(C14))
L15: =IF(C15="","",MONTH(C15)) | M15: =IF(C15="","",YEAR(C15)) | N15: =IF(C15="","",DAY(C15))
L16: =IF(C16="","",MONTH(C16)) | M16: =IF(C16="","",YEAR(C16)) | N16: =IF(C16="","",DAY(C16))
L17: =IF(C17="","",MONTH(C17)) | M17: =IF(C17="","",YEAR(C17)) | N17: =IF(C17="","",DAY(C17))
L18: =IF(C18="","",MONTH(C18)) | M18: =IF(C18="","",YEAR(C18)) | N18: =IF(C18="","",DAY(C18))
L19: =IF(C19="","",MONTH(C19)) | M19: =IF(C19="","",YEAR(C19)) | N19: =IF(C19="","",DAY(C19))
L20: =IF(C20="","",MONTH(C20)) | M20: =IF(C20="","",YEAR(C20)) | N20: =IF(C20="","",DAY(C20))
L21: =IF(C21="","",MONTH(C21)) | M21: =IF(C21="","",YEAR(C21)) | N21: =IF(C21="","",DAY(C21))
L22: =IF(C22="","",MONTH(C22)) | M22: =IF(C22="","",YEAR(C22)) | N22: =IF(C22="","",DAY(C22))
L23: =IF(C23="","",MONTH(C23)) | M23: =IF(C23="","",YEAR(C23)) | N23: =IF(C23="","",DAY(C23))
L24: =IF(C24="","",MONTH(C24)) | M24: =IF(C24="","",YEAR(C24)) | N24: =IF(C24="","",DAY(C24))
L25: =IF(C25="","",MONTH(C25)) | M25: =IF(C25="","",YEAR(C25)) | N25: =IF(C25="","",DAY(C25))
... L76: =IF(C76="","",MONTH(C76)) | M76: =IF(C76="","",YEAR(C76)) | N76: =IF(C76="","",DAY(C76))
L77: =IF(#REF!="","",MONTH(#REF!)) -> #REF! | M77: =IF(#REF!="","",YEAR(#REF!)) -> #REF! | N77: =IF(#REF!="","",DAY(#REF!)) -> #REF!
L78: =IF(C78="","",MONTH(C78)) | M78: =IF(C78="","",YEAR(C78)) | N78: =IF(C78="","",DAY(C78))
L79: =IF(C79="","",MONTH(C79)) | M79: =IF(C79="","",YEAR(C79)) | N79: =IF(C79="","",DAY(C79))
L80: =IF(C80="","",MONTH(C80)) | M80: =IF(C80="","",YEAR(C80)) | N80: =IF(C80="","",DAY(C80))
L81: =IF(C81="","",MONTH(C81)) | M81: =IF(C81="","",YEAR(C81)) | N81: =IF(C81="","",DAY(C81))
L82: =IF(C82="","",MONTH(C82)) | M82: =IF(C82="","",YEAR(C82)) | N82: =IF(C82="","",DAY(C82))
L83: =IF(C83="","",MONTH(C83)) | M83: =IF(C83="","",YEAR(C83)) | N83: =IF(C83="","",DAY(C83))
L84: =IF(C84="","",MONTH(C84)) | M84: =IF(C84="","",YEAR(C84)) | N84: =IF(C84="","",DAY(C84))
L85: =IF(C85="","",MONTH(C85)) | M85: =IF(C85="","",YEAR(C85)) | N85: =IF(C85="","",DAY(C85))
L86: =IF(C86="","",MONTH(C86)) | M86: =IF(C86="","",YEAR(C86)) | N86: =IF(C86="","",DAY(C86))
L87: =IF(C87="","",MONTH(C87)) | M87: =IF(C87="","",YEAR(C87)) | N87: =IF(C87="","",DAY(C87))
L88: =IF(C88="","",MONTH(C88)) | M88: =IF(C88="","",YEAR(C88)) | N88: =IF(C88="","",DAY(C88))
L89: =IF(C89="","",MONTH(C89)) | M89: =IF(C89="","",YEAR(C89)) | N89: =IF(C89="","",DAY(C89))
... L144: =IF(C144="","",MONTH(C144)) | M144: =IF(C144="","",YEAR(C144)) | N144: =IF(C144="","",DAY(C144))
I145: =G145 - (G145 / (1 + H145)) -> 0 | J145: =G145 / (1 + H145) -> 0 | L145: =IF(C145="","",MONTH(C145)) | M145: =IF(C145="","",YEAR(C145)) | N145: =IF(C145="","",DAY(C145))
I146: =G146 - (G146 / (1 + H146)) -> 0 | J146: =G146 / (1 + H146) -> 0 | L146: =IF(C146="","",MONTH(C146)) | M146: =IF(C146="","",YEAR(C146)) | N146: =IF(C146="","",DAY(C146))
I147: =G147 - (G147 / (1 + H147)) -> 0 | J147: =G147 / (1 + H147) -> 0 | L147: =IF(C147="","",MONTH(C147)) | M147: =IF(C147="","",YEAR(C147)) | N147: =IF(C147="","",DAY(C147))
I148: =G148 - (G148 / (1 + H148)) -> 0 | J148: =G148 / (1 + H148) -> 0 | L148: =IF(C148="","",MONTH(C148)) | M148: =IF(C148="","",YEAR(C148)) | N148: =IF(C148="","",DAY(C148))
...

Sheet Datos
B2: Ingresos | C2: =#REF! -> #REF! | D2: =#REF! -> #REF! | E2: =#REF! -> #REF! | F2: =#REF! -> #REF! | G2: =#REF! -> #REF! | H2: =#REF! -> #REF! | I2: =#REF! -> #REF! | J2: =#REF! -> #REF! | ... N2: =#REF! -> #REF! | O2: TOTAL | Q2: GASTOS | R2: =#REF! -> #REF! | S2: =#REF! -> #REF! | T2: =#REF! -> #REF! | U2: =#REF! -> #REF! | V2: =#REF! -> #REF! | W2: =#REF! -> #REF! | X2: =#REF! -> #REF! | Y2: =#REF! -> #REF! | ... AC2: =#REF! -> #REF! | AD2: TOTAL | AF2: Resumen anual: Ingresos vs Gastos
B3: M | C3: =IF(C2="","",MONTH(C2)) -> #REF! | D3: =IF(D2="","",MONTH(D2)) -> #REF! | E3: =IF(E2="","",MONTH(E2)) -> #REF! | F3: =IF(F2="","",MONTH(F2)) -> #REF! | G3: =IF(G2="","",MONTH(G2)) -> #REF! | H3: =IF(H2="","",MONTH(H2)) -> #REF! | I3: =IF(I2="","",MONTH(I2)) -> #REF! | J3: =IF(J2="","",MONTH(J2)) -> #REF! | ... N3: =IF(N2="","",MONTH(N2)) -> #REF! | Q3: M | R3: =IF(R2="","",MONTH(R2)) -> #REF! | S3: =IF(S2="","",MONTH(S2)) -> #REF! | T3: =IF(T2="","",MONTH(T2)) -> #REF! | U3: =IF(U2="","",MONTH(U2)) -> #REF! | V3: =IF(V2="","",MONTH(V2)) -> #REF! | W3: =IF(W2="","",MONTH(W2)) -> #REF! | X3: =IF(X2="","",MONTH(X2)) -> #REF! | Y3: =IF(Y2="","",MONTH(Y2)) -> #REF! | ... AC3: =IF(AC2="","",MONTH(AC2)) -> #REF! | AG3: Ingresos | AH3: Gastos | AI3: Costos | AM3: =#REF! -> #REF! | AN3: =#REF! -> #REF! | AO3: =#REF! -> #REF! | AP3: =#REF! -> #REF! | AQ3: =#REF! -> #REF! | AR3: =#REF! -> #REF! | AS3: =#REF! -> #REF! | AT3: =#REF! -> #REF! | ... AX3: =#REF! -> #REF!
B4: Y | C4: =IF(C2="","",YEAR(C2)) -> #REF! | D4: =IF(D2="","",YEAR(D2)) -> #REF! | E4: =IF(E2="","",YEAR(E2)) -> #REF! | F4: =IF(F2="","",YEAR(F2)) -> #REF! | G4: =IF(G2="","",YEAR(G2)) -> #REF! | H4: =IF(H2="","",YEAR(H2)) -> #REF! | I4: =IF(I2="","",YEAR(I2)) -> #REF! | J4: =IF(J2="","",YEAR(J2)) -> #REF! | ... N4: =IF(N2="","",YEAR(N2)) -> #REF! | Q4: Y | R4: =IF(R2="","",YEAR(R2)) -> #REF! | S4: =IF(S2="","",YEAR(S2)) -> #REF! | T4: =IF(T2="","",YEAR(T2)) -> #REF! | U4: =IF(U2="","",YEAR(U2)) -> #REF! | V4: =IF(V2="","",YEAR(V2)) -> #REF! | W4: =IF(W2="","",YEAR(W2)) -> #REF! | X4: =IF(X2="","",YEAR(X2)) -> #REF! | Y4: =IF(Y2="","",YEAR(Y2)) -> #REF! | ... AC4: =IF(AC2="","",YEAR(AC2)) -> #REF! | AF4: =#REF! -> #REF! | AG4: =#REF! -> #REF! | AH4: =#REF! -> #REF! | AI4: =#REF! -> #REF! | AM4: =IF(AM3="","",MONTH(AM3)) -> #REF! | AN4: =IF(AN3="","",MONTH(AN3)) -> #REF! | AO4: =IF(AO3="","",MONTH(AO3)) -> #REF! | AP4: =IF(AP3="","",MONTH(AP3)) -> #REF! | AQ4: =IF(AQ3="","",MONTH(AQ3)) -> #REF! | AR4: =IF(AR3="","",MONTH(AR3)) -> #REF! | AS4: =IF(AS3="","",MONTH(AS3)) -> #REF! | AT4: =IF(AT3="","",MONTH(AT3)) -> #REF! | ... AX4: =IF(AX3="","",MONTH(AX3)) -> #REF!
AF5: =#REF! -> #REF! | AG5: =#REF! -> #REF! | AH5: =#REF! -> #REF! | AI5: =#REF! -> #REF! | AM5: =IF(AM3="","",YEAR(AM3)) -> #REF! | AN5: =IF(AN3="","",YEAR(AN3)) -> #REF! | AO5: =IF(AO3="","",YEAR(AO3)) -> #REF! | AP5: =IF(AP3="","",YEAR(AP3)) -> #REF! | AQ5: =IF(AQ3="","",YEAR(AQ3)) -> #REF! | AR5: =IF(AR3="","",YEAR(AR3)) -> #REF! | AS5: =IF(AS3="","",YEAR(AS3)) -> #REF! | AT5: =IF(AT3="","",YEAR(AT3)) -> #REF! | ... AX5: =IF(AX3="","",YEAR(AX3)) -> #REF!
B6: CATEGORÍAS DE INGRESOS | Q6: CATEGORÍAS DE GASTOS | AF6: =#REF! -> #REF! | AG6: =#REF! -> #REF! | AH6: =#REF! -> #REF! | AI6: =#REF! -> #REF! | AK6: Ingresos Netos | AM6: =SUMIFS(Ingresos!$J$9:$J$3900,Ingresos!$L$9:$L$3900,$AM$4,Ingresos!$M$9:$M$3900,$AM$5) -> 0 | AN6: =SUMIFS(Ingresos!$J$9:$J$3900,Ingresos!$L$9:$L$3900,$AN$4,Ingresos!$M$9:$M$3900,$AN$5) -> 0 | AO6: =SUMIFS(Ingresos!$J$9:$J$3900,Ingresos!$L$9:$L$3900,$AO$4,Ingresos!$M$9:$M$3900,$AO$5) -> 0 | AP6: =SUMIFS(Ingresos!$J$9:$J$3900,Ingresos!$L$9:$L$3900,$AP$4,Ingresos!$M$9:$M$3900,$AP$5) -> 0 | AQ6: =SUMIFS(Ingresos!$J$9:$J$3900,Ingresos!$L$9:$L$3900,$AQ$4,Ingresos!$M$9:$M$3900,$AQ$5) -> 0 | AR6: =SUMIFS(Ingresos!$J$9:$J$3900,Ingresos!$L$9:$L$3900,$AR$4,Ingresos!$M$9:$M$3900,$AR$5) -> 0 | AS6: =SUMIFS(Ingresos!$J$9:$J$3900,Ingresos!$L$9:$L$3900,$AS$4,Ingresos!$M$9:$M$3900,$AS$5) -> 0 | AT6: =SUMIFS(Ingresos!$J$9:$J$3900,Ingresos!$L$9:$L$3900,$AT$4,Ingresos!$M$9:$M$3900,$AT$5) -> 0 | AU6: =SUMIFS(Ingresos!$J$9:$J$3900,Ingresos!$L$9:$L$3900,$AU$4,Ingresos!$M$9:$M$3900,$AU$5) -> 0 | AV6: =SUMIFS(Ingresos!$J$9:$J$3900,Ingresos!$L$9:$L$3900,$AV$4,Ingresos!$M$9:$M$3900,$AV$5) -> 0 | AW6: =SUMIFS(Ingresos!$J$9:$J$3900,Ingresos!$L$9:$L$3900,$AW$4,Ingresos!$M$9:$M$3900,$AW$5) -> 0 | AX6: =SUMIFS(Ingresos!$J$9:$J$3900,Ingresos!$L$9:$L$3900,$AX$4,Ingresos!$M$9:$M$3900,$AX$5) -> 0
B7: =#REF! -> #REF! | C7: =SUMIFS(Ingresos!$J$9:$J$3900, Ingresos!$L$9:$L$3900, $C$3, Ingresos!$M$9:$M$3900, $C$4, Ingresos!$D$9:$D$3900, B7) -> 0 | D7: =SUMIFS(Ingresos!$J$9:$J$3900, Ingresos!$L$9:$L$3900, $D$3, Ingresos!$M$9:$M$3900, $D$4, Ingresos!$D$9:$D$3900, B7) -> 0 | E7: =SUMIFS(Ingresos!$J$9:$J$3900, Ingresos!$L$9:$L$3900, $E$3, Ingresos!$M$9:$M$3900, $E$4, Ingresos!$D$9:$D$3900, B7) -> 0 | F7: =SUMIFS(Ingresos!$J$9:$J$3900, Ingresos!$L$9:$L$3900, $F$3, Ingresos!$M$9:$M$3900, $F$4, Ingresos!$D$9:$D$3900, B7) -> 0 | G7: =SUMIFS(Ingresos!$J$9:$J$3900, Ingresos!$L$9:$L$3900, $G$3, Ingresos!$M$9:$M$3900, $G$4, Ingresos!$D$9:$D$3900, B7) -> 0 | H7: =SUMIFS(Ingresos!$J$9:$J$3900, Ingresos!$L$9:$L$3900, $H$3, Ingresos!$M$9:$M$3900, $H$4, Ingresos!$D$9:$D$3900, B7) -> 0 | I7: =SUMIFS(Ingresos!$J$9:$J$3900, Ingresos!$L$9:$L$3900, $I$3, Ingresos!$M$9:$M$3900, $I$4, Ingresos!$D$9:$D$3900, B7) -> 0 | J7: =SUMIFS(Ingresos!$J$9:$J$3900, Ingresos!$L$9:$L$3900, $J$3, Ingresos!$M$9:$M$3900, $J$4, Ingresos!$D$9:$D$3900, B7) -> 0 | K7: =SUMIFS(Ingresos!$J$9:$J$3900, Ingresos!$L$9:$L$3900, $K$3, Ingresos!$M$9:$M$3900, $K$4, Ingresos!$D$9:$D$3900, B7) -> 0 | L7: =SUMIFS(Ingresos!$J$9:$J$3900, Ingresos!$L$9:$L$3900, $L$3, Ingresos!$M$9:$M$3900, $L$4, Ingresos!$D$9:$D$3900, B7) -> 0 | M7: =SUMIFS(Ingresos!$J$9:$J$3900, Ingresos!$L$9:$L$3900, $M$3, Ingresos!$M$9:$M$3900, $M$4, Ingresos!$D$9:$D$3900, B7) -> 0 | N7: =SUMIFS(Ingresos!$J$9:$J$3900, Ingresos!$L$9:$L$3900, $N$3, Ingresos!$M$9:$M$3900, $N$4, Ingresos!$D$9:$D$3900, B7) -> 0 | O7: =SUM(C7:N7) -> 0 | Q7: =#REF! -> #REF! | R7: =SUMIFS(Gastos!$J$9:$J$4091, Gastos!$L$9:$L$4091, $R$3, Gastos!$M$9:$M$4091, $R$4, Gastos!$D$9:$D$4091, Q7) -> 0 | S7: =SUMIFS(Gastos!$J$9:$J$4091, Gastos!$L$9:$L$4091, $S$3, Gastos!$M$9:$M$4091, $S$4, Gastos!$D$9:$D$4091, Q7) -> 0 | T7: =SUMIFS(Gastos!$J$9:$J$4091, Gastos!$L$9:$L$4091, $T$3, Gastos!$M$9:$M$4091, $T$4, Gastos!$D$9:$D$4091, Q7) -> 0 | U7: =SUMIFS(Gastos!$J$9:$J$4091, Gastos!$L$9:$L$4091, $U$3, Gastos!$M$9:$M$4091, $U$4, Gastos!$D$9:$D$4091, Q7) -> 0 | V7: =SUMIFS(Gastos!$J$9:$J$4091, Gastos!$L$9:$L$4091, $V$3, Gastos!$M$9:$M$4091, $V$4, Gastos!$D$9:$D$4091, Q7) -> 0 | W7: =SUMIFS(Gastos!$J$9:$J$4091, Gastos!$L$9:$L$4091, $W$3, Gastos!$M$9:$M$4091, $W$4, Gastos!$D$9:$D$4091, Q7) -> 0 | X7: =SUMIFS(Gastos!$J$9:$J$4091, Gastos!$L$9:$L$4091, $X$3, Gastos!$M$9:$M$4091, $X$4, Gastos!$D$9:$D$4091, Q7) -> 0 | Y7: =SUMIFS(Gastos!$J$9:$J$4091, Gastos!$L$9:$L$4091, $Y$3, Gastos!$M$9:$M$4091, $Y$4, Gastos!$D$9:$D$4091, Q7) -> 0 | Z7: =SUMIFS(Gastos!$J$9:$J$4091, Gastos!$L$9:$L$4091, $Z$3, Gastos!$M$9:$M$4091, $Z$4, Gastos!$D$9:$D$4091, Q7) -> 0 | AA7: =SUMIFS(Gastos!$J$9:$J$4091, Gastos!$L$9:$L$4091, $AA$3, Gastos!$M$9:$M$4091, $AA$4, Gastos!$D$9:$D$4091, Q7) -> 0 | AB7: =SUMIFS(Gastos!$J$9:$J$4091, Gastos!$L$9:$L$4091, $AB$3, Gastos!$M$9:$M$4091, $AB$4, Gastos!$D$9:$D$4091, Q7) -> 0 | AC7: =SUMIFS(Gastos!$J$9:$J$4091, Gastos!$L$9:$L$4091, $AC$3, Gastos!$M$9:$M$4091, $AC$4, Gastos!$D$9:$D$4091, Q7) -> 0 | AD7: =SUM(R7:AC7) -> 0 | AF7: =#REF! -> #REF! | AG7: =#REF! -> #REF! | AH7: =#REF! -> #REF! | AI7: =#REF! -> #REF! | AK7: Gastos y Costos Totales | AM7: =#REF!+#REF! -> #REF! | AN7: =#REF!+#REF! -> #REF! | AO7: =#REF!+#REF! -> #REF! | AP7: =#REF!+#REF! -> #REF! | AQ7: =#REF!+#REF! -> #REF! | AR7: =#REF!+#REF! -> #REF! | AS7: =#REF!+#REF! -> #REF! | AT7: =#REF!+#REF! -> #REF! | ... AX7: =#REF!+#REF! -> #REF!
B8: =#REF! -> #REF! | C8: =SUMIFS(Ingresos!$J$9:$J$3900, Ingresos!$L$9:$L$3900, $C$3, Ingresos!$M$9:$M$3900, $C$4, Ingresos!$D$9:$D$3900, B8) -> 0 | D8: =SUMIFS(Ingresos!$J$9:$J$3900, Ingresos!$L$9:$L$3900, $D$3, Ingresos!$M$9:$M$3900, $D$4, Ingresos!$D$9:$D$3900, B8) -> 0 | E8: =SUMIFS(Ingresos!$J$9:$J$3900, Ingresos!$L$9:$L$3900, $E$3, Ingresos!$M$9:$M$3900, $E$4, Ingresos!$D$9:$D$3900, B8) -> 0 | F8: =SUMIFS(Ingresos!$J$9:$J$3900, Ingresos!$L$9:$L$3900, $F$3, Ingresos!$M$9:$M$3900, $F$4, Ingresos!$D$9:$D$3900, B8) -> 0 | G8: =SUMIFS(Ingresos!$J$9:$J$3900, Ingresos!$L$9:$L$3900, $G$3, Ingresos!$M$9:$M$3900, $G$4, Ingresos!$D$9:$D$3900, B8) -> 0 | H8: =SUMIFS(Ingresos!$J$9:$J$3900, Ingresos!$L$9:$L$3900, $H$3, Ingresos!$M$9:$M$3900, $H$4, Ingresos!$D$9:$D$3900, B8) -> 0 | I8: =SUMIFS(Ingresos!$J$9:$J$3900, Ingresos!$L$9:$L$3900, $I$3, Ingresos!$M$9:$M$3900, $I$4, Ingresos!$D$9:$D$3900, B8) -> 0 | J8: =SUMIFS(Ingresos!$J$9:$J$3900, Ingresos!$L$9:$L$3900, $J$3, Ingresos!$M$9:$M$3900, $J$4, Ingresos!$D$9:$D$3900, B8) -> 0 | K8: =SUMIFS(Ingresos!$J$9:$J$3900, Ingresos!$L$9:$L$3900, $K$3, Ingresos!$M$9:$M$3900, $K$4, Ingresos!$D$9:$D$3900, B8) -> 0 | L8: =SUMIFS(Ingresos!$J$9:$J$3900, Ingresos!$L$9:$L$3900, $L$3, Ingresos!$M$9:$M$3900, $L$4, Ingresos!$D$9:$D$3900, B8) -> 0 | M8: =SUMIFS(Ingresos!$J$9:$J$3900, Ingresos!$L$9:$L$3900, $M$3, Ingresos!$M$9:$M$3900, $M$4, Ingresos!$D$9:$D$3900, B8) -> 0 | N8: =SUMIFS(Ingresos!$J$9:$J$3900, Ingresos!$L$9:$L$3900, $N$3, Ingresos!$M$9:$M$3900, $N$4, Ingresos!$D$9:$D$3900, B8) -> 0 | O8: =SUM(C8:N8) -> 0 | Q8: =#REF! -> #REF! | R8: =SUMIFS(Gastos!$J$9:$J$4091, Gastos!$L$9:$L$4091, $R$3, Gastos!$M$9:$M$4091, $R$4, Gastos!$D$9:$D$4091, Q8) -> 0 | S8: =SUMIFS(Gastos!$J$9:$J$4091, Gastos!$L$9:$L$4091, $S$3, Gastos!$M$9:$M$4091, $S$4, Gastos!$D$9:$D$4091, Q8) -> 0 | T8: =SUMIFS(Gastos!$J$9:$J$4091, Gastos!$L$9:$L$4091, $T$3, Gastos!$M$9:$M$4091, $T$4, Gastos!$D$9:$D$4091, Q8) -> 0 | U8: =SUMIFS(Gastos!$J$9:$J$4091, Gastos!$L$9:$L$4091, $U$3, Gastos!$M$9:$M$4091, $U$4, Gastos!$D$9:$D$4091, Q8) -> 0 | V8: =SUMIFS(Gastos!$J$9:$J$4091, Gastos!$L$9:$L$4091, $V$3, Gastos!$M$9:$M$4091, $V$4, Gastos!$D$9:$D$4091, Q8) -> 0 | W8: =SUMIFS(Gastos!$J$9:$J$4091, Gastos!$L$9:$L$4091, $W$3, Gastos!$M$9:$M$4091, $W$4, Gastos!$D$9:$D$4091, Q8) -> 0 | X8: =SUMIFS(Gastos!$J$9:$J$4091, Gastos!$L$9:$L$4091, $X$3, Gastos!$M$9:$M$4091, $X$4, Gastos!$D$9:$D$4091, Q8) -> 0 | Y8: =SUMIFS(Gastos!$J$9:$J$4091, Gastos!$L$9:$L$4091, $Y$3, Gastos!$M$9:$M$4091, $Y$4, Gastos!$D$9:$D$4091, Q8) -> 0 | Z8: =SUMIFS(Gastos!$J$9:$J$4091, Gastos!$L$9:$L$4091, $Z$3, Gastos!$M$9:$M$4091, $Z$4, Gastos!$D$9:$D$4091, Q8) -> 0 | AA8: =SUMIFS(Gastos!$J$9:$J$4091, Gastos!$L$9:$L$4091, $AA$3, Gastos!$M$9:$M$4091, $AA$4, Gastos!$D$9:$D$4091, Q8) -> 0 | AB8: =SUMIFS(Gastos!$J$9:$J$4091, Gastos!$L$9:$L$4091, $AB$3, Gastos!$M$9:$M$4091, $AB$4, Gastos!$D$9:$D$4091, Q8) -> 0 | AC8: =SUMIFS(Gastos!$J$9:$J$4091, Gastos!$L$9:$L$4091, $AC$3, Gastos!$M$9:$M$4091, $AC$4, Gastos!$D$9:$D$4091, Q8) -> 0 | AD8: =SUM(R8:AC8) -> 0 | AF8: =#REF! -> #REF! | AG8: =#REF! -> #REF! | AH8: =#REF! -> #REF! | AI8: =#REF! -> #REF!
B9: =#REF! -> #REF! | C9: =SUMIFS(Ingresos!$J$9:$J$3900, Ingresos!$L$9:$L$3900, $C$3, Ingresos!$M$9:$M$3900, $C$4, Ingresos!$D$9:$D$3900, B9) -> 0 | D9: =SUMIFS(Ingresos!$J$9:$J$3900, Ingresos!$L$9:$L$3900, $D$3, Ingresos!$M$9:$M$3900, $D$4, Ingresos!$D$9:$D$3900, B9) -> 0 | E9: =SUMIFS(Ingresos!$J$9:$J$3900, Ingresos!$L$9:$L$3900, $E$3, Ingresos!$M$9:$M$3900, $E$4, Ingresos!$D$9:$D$3900, B9) -> 0 | F9: =SUMIFS(Ingresos!$J$9:$J$3900, Ingresos!$L$9:$L$3900, $F$3, Ingresos!$M$9:$M$3900, $F$4, Ingresos!$D$9:$D$3900, B9) -> 0 | G9: =SUMIFS(Ingresos!$J$9:$J$3900, Ingresos!$L$9:$L$3900, $G$3, Ingresos!$M$9:$M$3900, $G$4, Ingresos!$D$9:$D$3900, B9) -> 0 | H9: =SUMIFS(Ingresos!$J$9:$J$3900, Ingresos!$L$9:$L$3900, $H$3, Ingresos!$M$9:$M$3900, $H$4, Ingresos!$D$9:$D$3900, B9) -> 0 | I9: =SUMIFS(Ingresos!$J$9:$J$3900, Ingresos!$L$9:$L$3900, $I$3, Ingresos!$M$9:$M$3900, $I$4, Ingresos!$D$9:$D$3900, B9) -> 0 | J9: =SUMIFS(Ingresos!$J$9:$J$3900, Ingresos!$L$9:$L$3900, $J$3, Ingresos!$M$9:$M$3900, $J$4, Ingresos!$D$9:$D$3900, B9) -> 0 | K9: =SUMIFS(Ingresos!$J$9:$J$3900, Ingresos!$L$9:$L$3900, $K$3, Ingresos!$M$9:$M$3900, $K$4, Ingresos!$D$9:$D$3900, B9) -> 0 | L9: =SUMIFS(Ingresos!$J$9:$J$3900, Ingresos!$L$9:$L$3900, $L$3, Ingresos!$M$9:$M$3900, $L$4, Ingresos!$D$9:$D$3900, B9) -> 0 | M9: =SUMIFS(Ingresos!$J$9:$J$3900, Ingresos!$L$9:$L$3900, $M$3, Ingresos!$M$9:$M$3900, $M$4, Ingresos!$D$9:$D$3900, B9) -> 0 | N9: =SUMIFS(Ingresos!$J$9:$J$3900, Ingresos!$L$9:$L$3900, $N$3, Ingresos!$M$9:$M$3900, $N$4, Ingresos!$D$9:$D$3900, B9) -> 0 | O9: =SUM(C9:N9) -> 0 | Q9: =#REF! -> #REF! | R9: =SUMIFS(Gastos!$J$9:$J$4091, Gastos!$L$9:$L$4091, $R$3, Gastos!$M$9:$M$4091, $R$4, Gastos!$D$9:$D$4091, Q9) -> 0 | S9: =SUMIFS(Gastos!$J$9:$J$4091, Gastos!$L$9:$L$4091, $S$3, Gastos!$M$9:$M$4091, $S$4, Gastos!$D$9:$D$4091, Q9) -> 0 | T9: =SUMIFS(Gastos!$J$9:$J$4091, Gastos!$L$9:$L$4091, $T$3, Gastos!$M$9:$M$4091, $T$4, Gastos!$D$9:$D$4091, Q9) -> 0 | U9: =SUMIFS(Gastos!$J$9:$J$4091, Gastos!$L$9:$L$4091, $U$3, Gastos!$M$9:$M$4091, $U$4, Gastos!$D$9:$D$4091, Q9) -> 0 | V9: =SUMIFS(Gastos!$J$9:$J$4091, Gastos!$L$9:$L$4091, $V$3, Gastos!$M$9:$M$4091, $V$4, Gastos!$D$9:$D$4091, Q9) -> 0 | W9: =SUMIFS(Gastos!$J$9:$J$4091, Gastos!$L$9:$L$4091, $W$3, Gastos!$M$9:$M$4091, $W$4, Gastos!$D$9:$D$4091, Q9) -> 0 | X9: =SUMIFS(Gastos!$J$9:$J$4091, Gastos!$L$9:$L$4091, $X$3, Gastos!$M$9:$M$4091, $X$4, Gastos!$D$9:$D$4091, Q9) -> 0 | Y9: =SUMIFS(Gastos!$J$9:$J$4091, Gastos!$L$9:$L$4091, $Y$3, Gastos!$M$9:$M$4091, $Y$4, Gastos!$D$9:$D$4091, Q9) -> 0 | Z9: =SUMIFS(Gastos!$J$9:$J$4091, Gastos!$L$9:$L$4091, $Z$3, Gastos!$M$9:$M$4091, $Z$4, Gastos!$D$9:$D$4091, Q9) -> 0 | AA9: =SUMIFS(Gastos!$J$9:$J$4091, Gastos!$L$9:$L$4091, $AA$3, Gastos!$M$9:$M$4091, $AA$4, Gastos!$D$9:$D$4091, Q9) -> 0 | AB9: =SUMIFS(Gastos!$J$9:$J$4091, Gastos!$L$9:$L$4091, $AB$3, Gastos!$M$9:$M$4091, $AB$4, Gastos!$D$9:$D$4091, Q9) -> 0 | AC9: =SUMIFS(Gastos!$J$9:$J$4091, Gastos!$L$9:$L$4091, $AC$3, Gastos!$M$9:$M$4091, $AC$4, Gastos!$D$9:$D$4091, Q9) -> 0 | AD9: =SUM(R9:AC9) -> 0 | AF9: =#REF! -> #REF! | AG9: =#REF! -> #REF! | AH9: =#REF! -> #REF! | AI9: =#REF! -> #REF! | AK9: Reaultado por Mes | AM9: =AM6-AM7 -> #REF! | AN9: =AN6-AN7 -> #REF! | AO9: =AO6-AO7 -> #REF! | AP9: =AP6-AP7 -> #REF! | AQ9: =AQ6-AQ7 -> #REF! | AR9: =AR6-AR7 -> #REF! | AS9: =AS6-AS7 -> #REF! | AT9: =AT6-AT7 -> #REF! | ... AX9: =AX6-AX7 -> #REF!
B10: =#REF! -> #REF! | C10: =SUMIFS(Ingresos!$J$9:$J$3900, Ingresos!$L$9:$L$3900, $C$3, Ingresos!$M$9:$M$3900, $C$4, Ingresos!$D$9:$D$3900, B10) -> 0 | D10: =SUMIFS(Ingresos!$J$9:$J$3900, Ingresos!$L$9:$L$3900, $D$3, Ingresos!$M$9:$M$3900, $D$4, Ingresos!$D$9:$D$3900, B10) -> 0 | E10: =SUMIFS(Ingresos!$J$9:$J$3900, Ingresos!$L$9:$L$3900, $E$3, Ingresos!$M$9:$M$3900, $E$4, Ingresos!$D$9:$D$3900, B10) -> 0 | F10: =SUMIFS(Ingresos!$J$9:$J$3900, Ingresos!$L$9:$L$3900, $F$3, Ingresos!$M$9:$M$3900, $F$4, Ingresos!$D$9:$D$3900, B10) -> 0 | G10: =SUMIFS(Ingresos!$J$9:$J$3900, Ingresos!$L$9:$L$3900, $G$3, Ingresos!$M$9:$M$3900, $G$4, Ingresos!$D$9:$D$3900, B10) -> 0 | H10: =SUMIFS(Ingresos!$J$9:$J$3900, Ingresos!$L$9:$L$3900, $H$3, Ingresos!$M$9:$M$3900, $H$4, Ingresos!$D$9:$D$3900, B10) -> 0 | I10: =SUMIFS(Ingresos!$J$9:$J$3900, Ingresos!$L$9:$L$3900, $I$3, Ingresos!$M$9:$M$3900, $I$4, Ingresos!$D$9:$D$3900, B10) -> 0 | J10: =SUMIFS(Ingresos!$J$9:$J$3900, Ingresos!$L$9:$L$3900, $J$3, Ingresos!$M$9:$M$3900, $J$4, Ingresos!$D$9:$D$3900, B10) -> 0 | K10: =SUMIFS(Ingresos!$J$9:$J$3900, Ingresos!$L$9:$L$3900, $K$3, Ingresos!$M$9:$M$3900, $K$4, Ingresos!$D$9:$D$3900, B10) -> 0 | L10: =SUMIFS(Ingresos!$J$9:$J$3900, Ingresos!$L$9:$L$3900, $L$3, Ingresos!$M$9:$M$3900, $L$4, Ingresos!$D$9:$D$3900, B10) -> 0 | M10: =SUMIFS(Ingresos!$J$9:$J$3900, Ingresos!$L$9:$L$3900, $M$3, Ingresos!$M$9:$M$3900, $M$4, Ingresos!$D$9:$D$3900, B10) -> 0 | N10: =SUMIFS(Ingresos!$J$9:$J$3900, Ingresos!$L$9:$L$3900, $N$3, Ingresos!$M$9:$M$3900, $N$4, Ingresos!$D$9:$D$3900, B10) -> 0 | O10: =SUM(C10:N10) -> 0 | Q10: =#REF! -> #REF! | R10: =SUMIFS(Gastos!$J$9:$J$4091, Gastos!$L$9:$L$4091, $R$3, Gastos!$M$9:$M$4091, $R$4, Gastos!$D$9:$D$4091, Q10) -> 0 | S10: =SUMIFS(Gastos!$J$9:$J$4091, Gastos!$L$9:$L$4091, $S$3, Gastos!$M$9:$M$4091, $S$4, Gastos!$D$9:$D$4091, Q10) -> 0 | T10: =SUMIFS(Gastos!$J$9:$J$4091, Gastos!$L$9:$L$4091, $T$3, Gastos!$M$9:$M$4091, $T$4, Gastos!$D$9:$D$4091, Q10) -> 0 | U10: =SUMIFS(Gastos!$J$9:$J$4091, Gastos!$L$9:$L$4091, $U$3, Gastos!$M$9:$M$4091, $U$4, Gastos!$D$9:$D$4091, Q10) -> 0 | V10: =SUMIFS(Gastos!$J$9:$J$4091, Gastos!$L$9:$L$4091, $V$3, Gastos!$M$9:$M$4091, $V$4, Gastos!$D$9:$D$4091, Q10) -> 0 | W10: =SUMIFS(Gastos!$J$9:$J$4091, Gastos!$L$9:$L$4091, $W$3, Gastos!$M$9:$M$4091, $W$4, Gastos!$D$9:$D$4091, Q10) -> 0 | X10: =SUMIFS(Gastos!$J$9:$J$4091, Gastos!$L$9:$L$4091, $X$3, Gastos!$M$9:$M$4091, $X$4, Gastos!$D$9:$D$4091, Q10) -> 0 | Y10: =SUMIFS(Gastos!$J$9:$J$4091, Gastos!$L$9:$L$4091, $Y$3, Gastos!$M$9:$M$4091, $Y$4, Gastos!$D$9:$D$4091, Q10) -> 0 | Z10: =SUMIFS(Gastos!$J$9:$J$4091, Gastos!$L$9:$L$4091, $Z$3, Gastos!$M$9:$M$4091, $Z$4, Gastos!$D$9:$D$4091, Q10) -> 0 | AA10: =SUMIFS(Gastos!$J$9:$J$4091, Gastos!$L$9:$L$4091, $AA$3, Gastos!$M$9:$M$4091, $AA$4, Gastos!$D$9:$D$4091, Q10) -> 0 | AB10: =SUMIFS(Gastos!$J$9:$J$4091, Gastos!$L$9:$L$4091, $AB$3, Gastos!$M$9:$M$4091, $AB$4, Gastos!$D$9:$D$4091, Q10) -> 0 | AC10: =SUMIFS(Gastos!$J$9:$J$4091, Gastos!$L$9:$L$4091, $AC$3, Gastos!$M$9:$M$4091, $AC$4, Gastos!$D$9:$D$4091, Q10) -> 0 | AD10: =SUM(R10:AC10) -> 0 | AF10: =#REF! -> #REF! | AG10: =#REF! -> #REF! | AH10: =#REF! -> #REF! | AI10: =#REF! -> #REF!
B11: =#REF! -> #REF! | C11: =SUMIFS(Ingresos!$J$9:$J$3900, Ingresos!$L$9:$L$3900, $C$3, Ingresos!$M$9:$M$3900, $C$4, Ingresos!$D$9:$D$3900, B11) -> 0 | D11: =SUMIFS(Ingresos!$J$9:$J$3900, Ingresos!$L$9:$L$3900, $D$3, Ingresos!$M$9:$M$3900, $D$4, Ingresos!$D$9:$D$3900, B11) -> 0 | E11: =SUMIFS(Ingresos!$J$9:$J$3900, Ingresos!$L$9:$L$3900, $E$3, Ingresos!$M$9:$M$3900, $E$4, Ingresos!$D$9:$D$3900, B11) -> 0 | F11: =SUMIFS(Ingresos!$J$9:$J$3900, Ingresos!$L$9:$L$3900, $F$3, Ingresos!$M$9:$M$3900, $F$4, Ingresos!$D$9:$D$3900, B11) -> 0 | G11: =SUMIFS(Ingresos!$J$9:$J$3900, Ingresos!$L$9:$L$3900, $G$3, Ingresos!$M$9:$M$3900, $G$4, Ingresos!$D$9:$D$3900, B11) -> 0 | H11: =SUMIFS(Ingresos!$J$9:$J$3900, Ingresos!$L$9:$L$3900, $H$3, Ingresos!$M$9:$M$3900, $H$4, Ingresos!$D$9:$D$3900, B11) -> 0 | I11: =SUMIFS(Ingresos!$J$9:$J$3900, Ingresos!$L$9:$L$3900, $I$3, Ingresos!$M$9:$M$3900, $I$4, Ingresos!$D$9:$D$3900, B11) -> 0 | J11: =SUMIFS(Ingresos!$J$9:$J$3900, Ingresos!$L$9:$L$3900, $J$3, Ingresos!$M$9:$M$3900, $J$4, Ingresos!$D$9:$D$3900, B11) -> 0 | K11: =SUMIFS(Ingresos!$J$9:$J$3900, Ingresos!$L$9:$L$3900, $K$3, Ingresos!$M$9:$M$3900, $K$4, Ingresos!$D$9:$D$3900, B11) -> 0 | L11: =SUMIFS(Ingresos!$J$9:$J$3900, Ingresos!$L$9:$L$3900, $L$3, Ingresos!$M$9:$M$3900, $L$4, Ingresos!$D$9:$D$3900, B11) -> 0 | M11: =SUMIFS(Ingresos!$J$9:$J$3900, Ingresos!$L$9:$L$3900, $M$3, Ingresos!$M$9:$M$3900, $M$4, Ingresos!$D$9:$D$3900, B11) -> 0 | N11: =SUMIFS(Ingresos!$J$9:$J$3900, Ingresos!$L$9:$L$3900, $N$3, Ingresos!$M$9:$M$3900, $N$4, Ingresos!$D$9:$D$3900, B11) -> 0 | O11: =SUM(C11:N11) -> 0 | Q11: =#REF! -> #REF! | R11: =SUMIFS(Gastos!$J$9:$J$4091, Gastos!$L$9:$L$4091, $R$3, Gastos!$M$9:$M$4091, $R$4, Gastos!$D$9:$D$4091, Q11) -> 0 | S11: =SUMIFS(Gastos!$J$9:$J$4091, Gastos!$L$9:$L$4091, $S$3, Gastos!$M$9:$M$4091, $S$4, Gastos!$D$9:$D$4091, Q11) -> 0 | T11: =SUMIFS(Gastos!$J$9:$J$4091, Gastos!$L$9:$L$4091, $T$3, Gastos!$M$9:$M$4091, $T$4, Gastos!$D$9:$D$4091, Q11) -> 0 | U11: =SUMIFS(Gastos!$J$9:$J$4091, Gastos!$L$9:$L$4091, $U$3, Gastos!$M$9:$M$4091, $U$4, Gastos!$D$9:$D$4091, Q11) -> 0 | V11: =SUMIFS(Gastos!$J$9:$J$4091, Gastos!$L$9:$L$4091, $V$3, Gastos!$M$9:$M$4091, $V$4, Gastos!$D$9:$D$4091, Q11) -> 0 | W11: =SUMIFS(Gastos!$J$9:$J$4091, Gastos!$L$9:$L$4091, $W$3, Gastos!$M$9:$M$4091, $W$4, Gastos!$D$9:$D$4091, Q11) -> 0 | X11: =SUMIFS(Gastos!$J$9:$J$4091, Gastos!$L$9:$L$4091, $X$3, Gastos!$M$9:$M$4091, $X$4, Gastos!$D$9:$D$4091, Q11) -> 0 | Y11: =SUMIFS(Gastos!$J$9:$J$4091, Gastos!$L$9:$L$4091, $Y$3, Gastos!$M$9:$M$4091, $Y$4, Gastos!$D$9:$D$4091, Q11) -> 0 | Z11: =SUMIFS(Gastos!$J$9:$J$4091, Gastos!$L$9:$L$4091, $Z$3, Gastos!$M$9:$M$4091, $Z$4, Gastos!$D$9:$D$4091, Q11) -> 0 | AA11: =SUMIFS(Gastos!$J$9:$J$4091, Gastos!$L$9:$L$4091, $AA$3, Gastos!$M$9:$M$4091, $AA$4, Gastos!$D$9:$D$4091, Q11) -> 0 | AB11: =SUMIFS(Gastos!$J$9:$J$4091, Gastos!$L$9:$L$4091, $AB$3, Gastos!$M$9:$M$4091, $AB$4, Gastos!$D$9:$D$4091, Q11) -> 0 | AC11: =SUMIFS(Gastos!$J$9:$J$4091, Gastos!$L$9:$L$4091, $AC$3, Gastos!$M$9:$M$4091, $AC$4, Gastos!$D$9:$D$4091, Q11) -> 0 | AD11: =SUM(R11:AC11) -> 0 | AF11: =#REF! -> #REF! | AG11: =#REF! -> #REF! | AH11: =#REF! -> #REF! | AI11: =#REF! -> #REF! | AK11: Saldo Acumulado | AM11: =AM9 -> #REF! | AN11: =AM11+AN9 -> #REF! | AO11: =AN11+AO9 -> #REF! | AP11: =AO11+AP9 -> #REF! | AQ11: =AP11+AQ9 -> #REF! | AR11: =AQ11+AR9 -> #REF! | AS11: =AR11+AS9 -> #REF! | AT11: =AS11+AT9 -> #REF! | AU11: =AT11+AU9 -> #REF! | ... AX11: =AW11+AX9 -> #REF!
B12: =#REF! -> #REF! | C12: =SUMIFS(Ingresos!$J$9:$J$3900, Ingresos!$L$9:$L$3900, $C$3, Ingresos!$M$9:$M$3900, $C$4, Ingresos!$D$9:$D$3900, B12) -> 0 | D12: =SUMIFS(Ingresos!$J$9:$J$3900, Ingresos!$L$9:$L$3900, $D$3, Ingresos!$M$9:$M$3900, $D$4, Ingresos!$D$9:$D$3900, B12) -> 0 | E12: =SUMIFS(Ingresos!$J$9:$J$3900, Ingresos!$L$9:$L$3900, $E$3, Ingresos!$M$9:$M$3900, $E$4, Ingresos!$D$9:$D$3900, B12) -> 0 | F12: =SUMIFS(Ingresos!$J$9:$J$3900, Ingresos!$L$9:$L$3900, $F$3, Ingresos!$M$9:$M$3900, $F$4, Ingresos!$D$9:$D$3900, B12) -> 0 | G12: =SUMIFS(Ingresos!$J$9:$J$3900, Ingresos!$L$9:$L$3900, $G$3, Ingresos!$M$9:$M$3900, $G$4, Ingresos!$D$9:$D$3900, B12) -> 0 | H12: =SUMIFS(Ingresos!$J$9:$J$3900, Ingresos!$L$9:$L$3900, $H$3, Ingresos!$M$9:$M$3900, $H$4, Ingresos!$D$9:$D$3900, B12) -> 0 | I12: =SUMIFS(Ingresos!$J$9:$J$3900, Ingresos!$L$9:$L$3900, $I$3, Ingresos!$M$9:$M$3900, $I$4, Ingresos!$D$9:$D$3900, B12) -> 0 | J12: =SUMIFS(Ingresos!$J$9:$J$3900, Ingresos!$L$9:$L$3900, $J$3, Ingresos!$M$9:$M$3900, $J$4, Ingresos!$D$9:$D$3900, B12) -> 0 | K12: =SUMIFS(Ingresos!$J$9:$J$3900, Ingresos!$L$9:$L$3900, $K$3, Ingresos!$M$9:$M$3900, $K$4, Ingresos!$D$9:$D$3900, B12) -> 0 | L12: =SUMIFS(Ingresos!$J$9:$J$3900, Ingresos!$L$9:$L$3900, $L$3, Ingresos!$M$9:$M$3900, $L$4, Ingresos!$D$9:$D$3900, B12) -> 0 | M12: =SUMIFS(Ingresos!$J$9:$J$3900, Ingresos!$L$9:$L$3900, $M$3, Ingresos!$M$9:$M$3900, $M$4, Ingresos!$D$9:$D$3900, B12) -> 0 | N12: =SUMIFS(Ingresos!$J$9:$J$3900, Ingresos!$L$9:$L$3900, $N$3, Ingresos!$M$9:$M$3900, $N$4, Ingresos!$D$9:$D$3900, B12) -> 0 | O12: =SUM(C12:N12) -> 0 | Q12: =#REF! -> #REF! | R12: =SUMIFS(Gastos!$J$9:$J$4091, Gastos!$L$9:$L$4091, $R$3, Gastos!$M$9:$M$4091, $R$4, Gastos!$D$9:$D$4091, Q12) -> 0 | S12: =SUMIFS(Gastos!$J$9:$J$4091, Gastos!$L$9:$L$4091, $S$3, Gastos!$M$9:$M$4091, $S$4, Gastos!$D$9:$D$4091, Q12) -> 0 | T12: =SUMIFS(Gastos!$J$9:$J$4091, Gastos!$L$9:$L$4091, $T$3, Gastos!$M$9:$M$4091, $T$4, Gastos!$D$9:$D$4091, Q12) -> 0 | U12: =SUMIFS(Gastos!$J$9:$J$4091, Gastos!$L$9:$L$4091, $U$3, Gastos!$M$9:$M$4091, $U$4, Gastos!$D$9:$D$4091, Q12) -> 0 | V12: =SUMIFS(Gastos!$J$9:$J$4091, Gastos!$L$9:$L$4091, $V$3, Gastos!$M$9:$M$4091, $V$4, Gastos!$D$9:$D$4091, Q12) -> 0 | W12: =SUMIFS(Gastos!$J$9:$J$4091, Gastos!$L$9:$L$4091, $W$3, Gastos!$M$9:$M$4091, $W$4, Gastos!$D$9:$D$4091, Q12) -> 0 | X12: =SUMIFS(Gastos!$J$9:$J$4091, Gastos!$L$9:$L$4091, $X$3, Gastos!$M$9:$M$4091, $X$4, Gastos!$D$9:$D$4091, Q12) -> 0 | Y12: =SUMIFS(Gastos!$J$9:$J$4091, Gastos!$L$9:$L$4091, $Y$3, Gastos!$M$9:$M$4091, $Y$4, Gastos!$D$9:$D$4091, Q12) -> 0 | Z12: =SUMIFS(Gastos!$J$9:$J$4091, Gastos!$L$9:$L$4091, $Z$3, Gastos!$M$9:$M$4091, $Z$4, Gastos!$D$9:$D$4091, Q12) -> 0 | AA12: =SUMIFS(Gastos!$J$9:$J$4091, Gastos!$L$9:$L$4091, $AA$3, Gastos!$M$9:$M$4091, $AA$4, Gastos!$D$9:$D$4091, Q12) -> 0 | AB12: =SUMIFS(Gastos!$J$9:$J$4091, Gastos!$L$9:$L$4091, $AB$3, Gastos!$M$9:$M$4091, $AB$4, Gastos!$D$9:$D$4091, Q12) -> 0 | AC12: =SUMIFS(Gastos!$J$9:$J$4091, Gastos!$L$9:$L$4091, $AC$3, Gastos!$M$9:$M$4091, $AC$4, Gastos!$D$9:$D$4091, Q12) -> 0 | AD12: =SUM(R12:AC12) -> 0 | AF12: =#REF! -> #REF! | AG12: =#REF! -> #REF! | AH12: =#REF! -> #REF! | AI12: =#REF! -> #REF!
B13: =#REF! -> #REF! | C13: =SUMIFS(Ingresos!$J$9:$J$3900, Ingresos!$L$9:$L$3900, $C$3, Ingresos!$M$9:$M$3900, $C$4, Ingresos!$D$9:$D$3900, B13) -> 0 | D13: =SUMIFS(Ingresos!$J$9:$J$3900, Ingresos!$L$9:$L$3900, $D$3, Ingresos!$M$9:$M$3900, $D$4, Ingresos!$D$9:$D$3900, B13) -> 0 | E13: =SUMIFS(Ingresos!$J$9:$J$3900, Ingresos!$L$9:$L$3900, $E$3, Ingresos!$M$9:$M$3900, $E$4, Ingresos!$D$9:$D$3900, B13) -> 0 | F13: =SUMIFS(Ingresos!$J$9:$J$3900, Ingresos!$L$9:$L$3900, $F$3, Ingresos!$M$9:$M$3900, $F$4, Ingresos!$D$9:$D$3900, B13) -> 0 | G13: =SUMIFS(Ingresos!$J$9:$J$3900, Ingresos!$L$9:$L$3900, $G$3, Ingresos!$M$9:$M$3900, $G$4, Ingresos!$D$9:$D$3900, B13) -> 0 | H13: =SUMIFS(Ingresos!$J$9:$J$3900, Ingresos!$L$9:$L$3900, $H$3, Ingresos!$M$9:$M$3900, $H$4, Ingresos!$D$9:$D$3900, B13) -> 0 | I13: =SUMIFS(Ingresos!$J$9:$J$3900, Ingresos!$L$9:$L$3900, $I$3, Ingresos!$M$9:$M$3900, $I$4, Ingresos!$D$9:$D$3900, B13) -> 0 | J13: =SUMIFS(Ingresos!$J$9:$J$3900, Ingresos!$L$9:$L$3900, $J$3, Ingresos!$M$9:$M$3900, $J$4, Ingresos!$D$9:$D$3900, B13) -> 0 | K13: =SUMIFS(Ingresos!$J$9:$J$3900, Ingresos!$L$9:$L$3900, $K$3, Ingresos!$M$9:$M$3900, $K$4, Ingresos!$D$9:$D$3900, B13) -> 0 | L13: =SUMIFS(Ingresos!$J$9:$J$3900, Ingresos!$L$9:$L$3900, $L$3, Ingresos!$M$9:$M$3900, $L$4, Ingresos!$D$9:$D$3900, B13) -> 0 | M13: =SUMIFS(Ingresos!$J$9:$J$3900, Ingresos!$L$9:$L$3900, $M$3, Ingresos!$M$9:$M$3900, $M$4, Ingresos!$D$9:$D$3900, B13) -> 0 | N13: =SUMIFS(Ingresos!$J$9:$J$3900, Ingresos!$L$9:$L$3900, $N$3, Ingresos!$M$9:$M$3900, $N$4, Ingresos!$D$9:$D$3900, B13) -> 0 | O13: =SUM(C13:N13) -> 0 | Q13: =#REF! -> #REF! | R13: =SUMIFS(Gastos!$J$9:$J$4091, Gastos!$L$9:$L$4091, $R$3, Gastos!$M$9:$M$4091, $R$4, Gastos!$D$9:$D$4091, Q13) -> 0 | S13: =SUMIFS(Gastos!$J$9:$J$4091, Gastos!$L$9:$L$4091, $S$3, Gastos!$M$9:$M$4091, $S$4, Gastos!$D$9:$D$4091, Q13) -> 0 | T13: =SUMIFS(Gastos!$J$9:$J$4091, Gastos!$L$9:$L$4091, $T$3, Gastos!$M$9:$M$4091, $T$4, Gastos!$D$9:$D$4091, Q13) -> 0 | U13: =SUMIFS(Gastos!$J$9:$J$4091, Gastos!$L$9:$L$4091, $U$3, Gastos!$M$9:$M$4091, $U$4, Gastos!$D$9:$D$4091, Q13) -> 0 | V13: =SUMIFS(Gastos!$J$9:$J$4091, Gastos!$L$9:$L$4091, $V$3, Gastos!$M$9:$M$4091, $V$4, Gastos!$D$9:$D$4091, Q13) -> 0 | W13: =SUMIFS(Gastos!$J$9:$J$4091, Gastos!$L$9:$L$4091, $W$3, Gastos!$M$9:$M$4091, $W$4, Gastos!$D$9:$D$4091, Q13) -> 0 | X13: =SUMIFS(Gastos!$J$9:$J$4091, Gastos!$L$9:$L$4091, $X$3, Gastos!$M$9:$M$4091, $X$4, Gastos!$D$9:$D$4091, Q13) -> 0 | Y13: =SUMIFS(Gastos!$J$9:$J$4091, Gastos!$L$9:$L$4091, $Y$3, Gastos!$M$9:$M$4091, $Y$4, Gastos!$D$9:$D$4091, Q13) -> 0 | Z13: =SUMIFS(Gastos!$J$9:$J$4091, Gastos!$L$9:$L$4091, $Z$3, Gastos!$M$9:$M$4091, $Z$4, Gastos!$D$9:$D$4091, Q13) -> 0 | AA13: =SUMIFS(Gastos!$J$9:$J$4091, Gastos!$L$9:$L$4091, $AA$3, Gastos!$M$9:$M$4091, $AA$4, Gastos!$D$9:$D$4091, Q13) -> 0 | AB13: =SUMIFS(Gastos!$J$9:$J$4091, Gastos!$L$9:$L$4091, $AB$3, Gastos!$M$9:$M$4091, $AB$4, Gastos!$D$9:$D$4091, Q13) -> 0 | AC13: =SUMIFS(Gastos!$J$9:$J$4091, Gastos!$L$9:$L$4091, $AC$3, Gastos!$M$9:$M$4091, $AC$4, Gastos!$D$9:$D$4091, Q13) -> 0 | AD13: =SUM(R13:AC13) -> 0 | AF13: =#REF! -> #REF! | AG13: =#REF! -> #REF! | AH13: =#REF! -> #REF! | AI13: =#REF! -> #REF!
B14: =#REF! -> #REF! | C14: =SUMIFS(Ingresos!$J$9:$J$3900, Ingresos!$L$9:$L$3900, $C$3, Ingresos!$M$9:$M$3900, $C$4, Ingresos!$D$9:$D$3900, B14) -> 0 | D14: =SUMIFS(Ingresos!$J$9:$J$3900, Ingresos!$L$9:$L$3900, $D$3, Ingresos!$M$9:$M$3900, $D$4, Ingresos!$D$9:$D$3900, B14) -> 0 | E14: =SUMIFS(Ingresos!$J$9:$J$3900, Ingresos!$L$9:$L$3900, $E$3, Ingresos!$M$9:$M$3900, $E$4, Ingresos!$D$9:$D$3900, B14) -> 0 | F14: =SUMIFS(Ingresos!$J$9:$J$3900, Ingresos!$L$9:$L$3900, $F$3, Ingresos!$M$9:$M$3900, $F$4, Ingresos!$D$9:$D$3900, B14) -> 0 | G14: =SUMIFS(Ingresos!$J$9:$J$3900, Ingresos!$L$9:$L$3900, $G$3, Ingresos!$M$9:$M$3900, $G$4, Ingresos!$D$9:$D$3900, B14) -> 0 | H14: =SUMIFS(Ingresos!$J$9:$J$3900, Ingresos!$L$9:$L$3900, $H$3, Ingresos!$M$9:$M$3900, $H$4, Ingresos!$D$9:$D$3900, B14) -> 0 | I14: =SUMIFS(Ingresos!$J$9:$J$3900, Ingresos!$L$9:$L$3900, $I$3, Ingresos!$M$9:$M$3900, $I$4, Ingresos!$D$9:$D$3900, B14) -> 0 | J14: =SUMIFS(Ingresos!$J$9:$J$3900, Ingresos!$L$9:$L$3900, $J$3, Ingresos!$M$9:$M$3900, $J$4, Ingresos!$D$9:$D$3900, B14) -> 0 | K14: =SUMIFS(Ingresos!$J$9:$J$3900, Ingresos!$L$9:$L$3900, $K$3, Ingresos!$M$9:$M$3900, $K$4, Ingresos!$D$9:$D$3900, B14) -> 0 | L14: =SUMIFS(Ingresos!$J$9:$J$3900, Ingresos!$L$9:$L$3900, $L$3, Ingresos!$M$9:$M$3900, $L$4, Ingresos!$D$9:$D$3900, B14) -> 0 | M14: =SUMIFS(Ingresos!$J$9:$J$3900, Ingresos!$L$9:$L$3900, $M$3, Ingresos!$M$9:$M$3900, $M$4, Ingresos!$D$9:$D$3900, B14) -> 0 | N14: =SUMIFS(Ingresos!$J$9:$J$3900, Ingresos!$L$9:$L$3900, $N$3, Ingresos!$M$9:$M$3900, $N$4, Ingresos!$D$9:$D$3900, B14) -> 0 | O14: =SUM(C14:N14) -> 0 | Q14: =#REF! -> #REF! | R14: =SUMIFS(Gastos!$J$9:$J$4091, Gastos!$L$9:$L$4091, $R$3, Gastos!$M$9:$M$4091, $R$4, Gastos!$D$9:$D$4091, Q14) -> 0 | S14: =SUMIFS(Gastos!$J$9:$J$4091, Gastos!$L$9:$L$4091, $S$3, Gastos!$M$9:$M$4091, $S$4, Gastos!$D$9:$D$4091, Q14) -> 0 | T14: =SUMIFS(Gastos!$J$9:$J$4091, Gastos!$L$9:$L$4091, $T$3, Gastos!$M$9:$M$4091, $T$4, Gastos!$D$9:$D$4091, Q14) -> 0 | U14: =SUMIFS(Gastos!$J$9:$J$4091, Gastos!$L$9:$L$4091, $U$3, Gastos!$M$9:$M$4091, $U$4, Gastos!$D$9:$D$4091, Q14) -> 0 | V14: =SUMIFS(Gastos!$J$9:$J$4091, Gastos!$L$9:$L$4091, $V$3, Gastos!$M$9:$M$4091, $V$4, Gastos!$D$9:$D$4091, Q14) -> 0 | W14: =SUMIFS(Gastos!$J$9:$J$4091, Gastos!$L$9:$L$4091, $W$3, Gastos!$M$9:$M$4091, $W$4, Gastos!$D$9:$D$4091, Q14) -> 0 | X14: =SUMIFS(Gastos!$J$9:$J$4091, Gastos!$L$9:$L$4091, $X$3, Gastos!$M$9:$M$4091, $X$4, Gastos!$D$9:$D$4091, Q14) -> 0 | Y14: =SUMIFS(Gastos!$J$9:$J$4091, Gastos!$L$9:$L$4091, $Y$3, Gastos!$M$9:$M$4091, $Y$4, Gastos!$D$9:$D$4091, Q14) -> 0 | Z14: =SUMIFS(Gastos!$J$9:$J$4091, Gastos!$L$9:$L$4091, $Z$3, Gastos!$M$9:$M$4091, $Z$4, Gastos!$D$9:$D$4091, Q14) -> 0 | AA14: =SUMIFS(Gastos!$J$9:$J$4091, Gastos!$L$9:$L$4091, $AA$3, Gastos!$M$9:$M$4091, $AA$4, Gastos!$D$9:$D$4091, Q14) -> 0 | AB14: =SUMIFS(Gastos!$J$9:$J$4091, Gastos!$L$9:$L$4091, $AB$3, Gastos!$M$9:$M$4091, $AB$4, Gastos!$D$9:$D$4091, Q14) -> 0 | AC14: =SUMIFS(Gastos!$J$9:$J$4091, Gastos!$L$9:$L$4091, $AC$3, Gastos!$M$9:$M$4091, $AC$4, Gastos!$D$9:$D$4091, Q14) -> 0 | AD14: =SUM(R14:AC14) -> 0 | AF14: =#REF! -> #REF! | AG14: =#REF! -> #REF! | AH14: =#REF! -> #REF! | AI14: =#REF! -> #REF! | AK14: INGRESOS | AL14: Presupuesto | AM14: Actual | AN14: Variación | AO14: Pre. Acumulativo | AP14: Ingreso Acumulativo
B15: =#REF! -> #REF! | C15: =SUMIFS(Ingresos!$J$9:$J$3900, Ingresos!$L$9:$L$3900, $C$3, Ingresos!$M$9:$M$3900, $C$4, Ingresos!$D$9:$D$3900, B15) -> 0 | D15: =SUMIFS(Ingresos!$J$9:$J$3900, Ingresos!$L$9:$L$3900, $D$3, Ingresos!$M$9:$M$3900, $D$4, Ingresos!$D$9:$D$3900, B15) -> 0 | E15: =SUMIFS(Ingresos!$J$9:$J$3900, Ingresos!$L$9:$L$3900, $E$3, Ingresos!$M$9:$M$3900, $E$4, Ingresos!$D$9:$D$3900, B15) -> 0 | F15: =SUMIFS(Ingresos!$J$9:$J$3900, Ingresos!$L$9:$L$3900, $F$3, Ingresos!$M$9:$M$3900, $F$4, Ingresos!$D$9:$D$3900, B15) -> 0 | G15: =SUMIFS(Ingresos!$J$9:$J$3900, Ingresos!$L$9:$L$3900, $G$3, Ingresos!$M$9:$M$3900, $G$4, Ingresos!$D$9:$D$3900, B15) -> 0 | H15: =SUMIFS(Ingresos!$J$9:$J$3900, Ingresos!$L$9:$L$3900, $H$3, Ingresos!$M$9:$M$3900, $H$4, Ingresos!$D$9:$D$3900, B15) -> 0 | I15: =SUMIFS(Ingresos!$J$9:$J$3900, Ingresos!$L$9:$L$3900, $I$3, Ingresos!$M$9:$M$3900, $I$4, Ingresos!$D$9:$D$3900, B15) -> 0 | J15: =SUMIFS(Ingresos!$J$9:$J$3900, Ingresos!$L$9:$L$3900, $J$3, Ingresos!$M$9:$M$3900, $J$4, Ingresos!$D$9:$D$3900, B15) -> 0 | K15: =SUMIFS(Ingresos!$J$9:$J$3900, Ingresos!$L$9:$L$3900, $K$3, Ingresos!$M$9:$M$3900, $K$4, Ingresos!$D$9:$D$3900, B15) -> 0 | L15: =SUMIFS(Ingresos!$J$9:$J$3900, Ingresos!$L$9:$L$3900, $L$3, Ingresos!$M$9:$M$3900, $L$4, Ingresos!$D$9:$D$3900, B15) -> 0 | M15: =SUMIFS(Ingresos!$J$9:$J$3900, Ingresos!$L$9:$L$3900, $M$3, Ingresos!$M$9:$M$3900, $M$4, Ingresos!$D$9:$D$3900, B15) -> 0 | N15: =SUMIFS(Ingresos!$J$9:$J$3900, Ingresos!$L$9:$L$3900, $N$3, Ingresos!$M$9:$M$3900, $N$4, Ingresos!$D$9:$D$3900, B15) -> 0 | O15: =SUM(C15:N15) -> 0 | Q15: =#REF! -> #REF! | R15: =SUMIFS(Gastos!$J$9:$J$4091, Gastos!$L$9:$L$4091, $R$3, Gastos!$M$9:$M$4091, $R$4, Gastos!$D$9:$D$4091, Q15) -> 0 | S15: =SUMIFS(Gastos!$J$9:$J$4091, Gastos!$L$9:$L$4091, $S$3, Gastos!$M$9:$M$4091, $S$4, Gastos!$D$9:$D$4091, Q15) -> 0 | T15: =SUMIFS(Gastos!$J$9:$J$4091, Gastos!$L$9:$L$4091, $T$3, Gastos!$M$9:$M$4091, $T$4, Gastos!$D$9:$D$4091, Q15) -> 0 | U15: =SUMIFS(Gastos!$J$9:$J$4091, Gastos!$L$9:$L$4091, $U$3, Gastos!$M$9:$M$4091, $U$4, Gastos!$D$9:$D$4091, Q15) -> 0 | V15: =SUMIFS(Gastos!$J$9:$J$4091, Gastos!$L$9:$L$4091, $V$3, Gastos!$M$9:$M$4091, $V$4, Gastos!$D$9:$D$4091, Q15) -> 0 | W15: =SUMIFS(Gastos!$J$9:$J$4091, Gastos!$L$9:$L$4091, $W$3, Gastos!$M$9:$M$4091, $W$4, Gastos!$D$9:$D$4091, Q15) -> 0 | X15: =SUMIFS(Gastos!$J$9:$J$4091, Gastos!$L$9:$L$4091, $X$3, Gastos!$M$9:$M$4091, $X$4, Gastos!$D$9:$D$4091, Q15) -> 0 | Y15: =SUMIFS(Gastos!$J$9:$J$4091, Gastos!$L$9:$L$4091, $Y$3, Gastos!$M$9:$M$4091, $Y$4, Gastos!$D$9:$D$4091, Q15) -> 0 | Z15: =SUMIFS(Gastos!$J$9:$J$4091, Gastos!$L$9:$L$4091, $Z$3, Gastos!$M$9:$M$4091, $Z$4, Gastos!$D$9:$D$4091, Q15) -> 0 | AA15: =SUMIFS(Gastos!$J$9:$J$4091, Gastos!$L$9:$L$4091, $AA$3, Gastos!$M$9:$M$4091, $AA$4, Gastos!$D$9:$D$4091, Q15) -> 0 | AB15: =SUMIFS(Gastos!$J$9:$J$4091, Gastos!$L$9:$L$4091, $AB$3, Gastos!$M$9:$M$4091, $AB$4, Gastos!$D$9:$D$4091, Q15) -> 0 | AC15: =SUMIFS(Gastos!$J$9:$J$4091, Gastos!$L$9:$L$4091, $AC$3, Gastos!$M$9:$M$4091, $AC$4, Gastos!$D$9:$D$4091, Q15) -> 0 | AD15: =SUM(R15:AC15) -> 0 | AF15: =#REF! -> #REF! | AG15: =#REF! -> #REF! | AH15: =#REF! -> #REF! | AI15: =#REF! -> #REF! | AK15: =#REF! -> #REF! | AL15: =#REF! -> #REF! | AM15: =#REF! -> #REF! | AN15: =AL15-AM15 -> #REF! | AO15: =AL15 -> #REF! | AP15: =AM15 -> #REF!
B16: =#REF! -> #REF! | C16: =SUMIFS(Ingresos!$J$9:$J$3900, Ingresos!$L$9:$L$3900, $C$3, Ingresos!$M$9:$M$3900, $C$4, Ingresos!$D$9:$D$3900, B16) -> 0 | D16: =SUMIFS(Ingresos!$J$9:$J$3900, Ingresos!$L$9:$L$3900, $D$3, Ingresos!$M$9:$M$3900, $D$4, Ingresos!$D$9:$D$3900, B16) -> 0 | E16: =SUMIFS(Ingresos!$J$9:$J$3900, Ingresos!$L$9:$L$3900, $E$3, Ingresos!$M$9:$M$3900, $E$4, Ingresos!$D$9:$D$3900, B16) -> 0 | F16: =SUMIFS(Ingresos!$J$9:$J$3900, Ingresos!$L$9:$L$3900, $F$3, Ingresos!$M$9:$M$3900, $F$4, Ingresos!$D$9:$D$3900, B16) -> 0 | G16: =SUMIFS(Ingresos!$J$9:$J$3900, Ingresos!$L$9:$L$3900, $G$3, Ingresos!$M$9:$M$3900, $G$4, Ingresos!$D$9:$D$3900, B16) -> 0 | H16: =SUMIFS(Ingresos!$J$9:$J$3900, Ingresos!$L$9:$L$3900, $H$3, Ingresos!$M$9:$M$3900, $H$4, Ingresos!$D$9:$D$3900, B16) -> 0 | I16: =SUMIFS(Ingresos!$J$9:$J$3900, Ingresos!$L$9:$L$3900, $I$3, Ingresos!$M$9:$M$3900, $I$4, Ingresos!$D$9:$D$3900, B16) -> 0 | J16: =SUMIFS(Ingresos!$J$9:$J$3900, Ingresos!$L$9:$L$3900, $J$3, Ingresos!$M$9:$M$3900, $J$4, Ingresos!$D$9:$D$3900, B16) -> 0 | K16: =SUMIFS(Ingresos!$J$9:$J$3900, Ingresos!$L$9:$L$3900, $K$3, Ingresos!$M$9:$M$3900, $K$4, Ingresos!$D$9:$D$3900, B16) -> 0 | L16: =SUMIFS(Ingresos!$J$9:$J$3900, Ingresos!$L$9:$L$3900, $L$3, Ingresos!$M$9:$M$3900, $L$4, Ingresos!$D$9:$D$3900, B16) -> 0 | M16: =SUMIFS(Ingresos!$J$9:$J$3900, Ingresos!$L$9:$L$3900, $M$3, Ingresos!$M$9:$M$3900, $M$4, Ingresos!$D$9:$D$3900, B16) -> 0 | N16: =SUMIFS(Ingresos!$J$9:$J$3900, Ingresos!$L$9:$L$3900, $N$3, Ingresos!$M$9:$M$3900, $N$4, Ingresos!$D$9:$D$3900, B16) -> 0 | O16: =SUM(C16:N16) -> 0 | Q16: =#REF! -> #REF! | R16: =SUMIFS(Gastos!$J$9:$J$4091, Gastos!$L$9:$L$4091, $R$3, Gastos!$M$9:$M$4091, $R$4, Gastos!$D$9:$D$4091, Q16) -> 0 | S16: =SUMIFS(Gastos!$J$9:$J$4091, Gastos!$L$9:$L$4091, $S$3, Gastos!$M$9:$M$4091, $S$4, Gastos!$D$9:$D$4091, Q16) -> 0 | T16: =SUMIFS(Gastos!$J$9:$J$4091, Gastos!$L$9:$L$4091, $T$3, Gastos!$M$9:$M$4091, $T$4, Gastos!$D$9:$D$4091, Q16) -> 0 | U16: =SUMIFS(Gastos!$J$9:$J$4091, Gastos!$L$9:$L$4091, $U$3, Gastos!$M$9:$M$4091, $U$4, Gastos!$D$9:$D$4091, Q16) -> 0 | V16: =SUMIFS(Gastos!$J$9:$J$4091, Gastos!$L$9:$L$4091, $V$3, Gastos!$M$9:$M$4091, $V$4, Gastos!$D$9:$D$4091, Q16) -> 0 | W16: =SUMIFS(Gastos!$J$9:$J$4091, Gastos!$L$9:$L$4091, $W$3, Gastos!$M$9:$M$4091, $W$4, Gastos!$D$9:$D$4091, Q16) -> 0 | X16: =SUMIFS(Gastos!$J$9:$J$4091, Gastos!$L$9:$L$4091, $X$3, Gastos!$M$9:$M$4091, $X$4, Gastos!$D$9:$D$4091, Q16) -> 0 | Y16: =SUMIFS(Gastos!$J$9:$J$4091, Gastos!$L$9:$L$4091, $Y$3, Gastos!$M$9:$M$4091, $Y$4, Gastos!$D$9:$D$4091, Q16) -> 0 | Z16: =SUMIFS(Gastos!$J$9:$J$4091, Gastos!$L$9:$L$4091, $Z$3, Gastos!$M$9:$M$4091, $Z$4, Gastos!$D$9:$D$4091, Q16) -> 0 | AA16: =SUMIFS(Gastos!$J$9:$J$4091, Gastos!$L$9:$L$4091, $AA$3, Gastos!$M$9:$M$4091, $AA$4, Gastos!$D$9:$D$4091, Q16) -> 0 | AB16: =SUMIFS(Gastos!$J$9:$J$4091, Gastos!$L$9:$L$4091, $AB$3, Gastos!$M$9:$M$4091, $AB$4, Gastos!$D$9:$D$4091, Q16) -> 0 | AC16: =SUMIFS(Gastos!$J$9:$J$4091, Gastos!$L$9:$L$4091, $AC$3, Gastos!$M$9:$M$4091, $AC$4, Gastos!$D$9:$D$4091, Q16) -> 0 | AD16: =SUM(R16:AC16) -> 0 | AK16: =#REF! -> #REF! | AL16: =#REF! -> #REF! | AM16: =#REF! -> #REF! | AN16: =AL16-AM16 -> #REF! | AO16: =AO15+AL16 -> #REF! | AP16: =AP15+AM16 -> #REF!
